Workbook
Name FAMILIA_CON_NIÑO_NANEAS: #REF!
Name FAMILIA_CON_NIÑO_NANEAS: #REF!
Name FAMILIA_CON_NIÑO_NANEAS: #REF!

Sheet NOMBRE
A1: DATOS DEL ESTABLECIMIENTO | C1: CÓDIGOS
A2: NOMBRE DE COMUNA | I2: =IF(OR(NOMBRE!C2="",NOMBRE!D2="",NOMBRE!E2="",NOMBRE!F2="",NOMBRE!G2=""),"Falta Cód. Com.","") -> Falta Cód. Com. | AG2: =IF(I2>"",1,0) -> 1
A3: NOMBRE ESTABLECIMIENTO/ESTRATEGIA | I3: =IF(OR(NOMBRE!C3="",NOMBRE!D3="",NOMBRE!E3="",NOMBRE!F3="",NOMBRE!G3="",NOMBRE!H3=""),"Falta Cód. Est.","") -> Falta Cód. Est. | AG3: =IF(I3>"",1,0) -> 1
A4: TIPO DE ESTABLECIMIENTO/ESTRATEGIA | I4: =IF(OR(NOMBRE!B4=""),"Falta Tipo. Est.","") -> Falta Tipo. Est. | AG4: =IF(I4>"",1,0) -> 1
A5: DEPENDENCIA | I5: =IF(OR(NOMBRE!B5=""),"Falta Dependencia. Est.","") -> Falta Dependencia. Est. | AG5: =IF(I5>"",1,0) -> 1
A6: MES: | I6: =IF(OR(NOMBRE!C6="",NOMBRE!D6=""),"Falta Cód. Mes.","") -> Falta Cód. Mes. | AG6: =IF(I6>"",1,0) -> 1
A7: AÑO: | B7: 2020 | AG7: =SUM(AG2:AG6) -> 5
A9: Versión 1.1: ENERO 2020 | G9: Para habilitar el contenido de las celdas "Tipo de Establecimiento", "Dependencia" y "Mes", presione el boton "Verificar Habilitacion de Macros". Para poder tener un 100% de funcionalidad debe hablitar la opcion Macros en esta planilla.
A11: Director Servicio de Salud o Director Establecimiento | AA11: ENERO | AB11: Establecimiento de Mayor Complejidad (EMAYC) | AC11: SERVICIO DE SALUD
A12: Jefe de Estadísticas | AA12: FEBRERO | AB12: Establecimiento de Mediana Complejidad (EMEDC) | AC12: MUNICIPAL
AA13: MARZO | AB13: Establecimiento de Menor Complejidad (EMENC) | AC13: OTRA INSTITUCIÓN (Delegado)
AA14: ABRIL | AB14: Centros de Diagnóstico Terapéutico (CDT)
A15: MINSAL - DEIS | AA15: MAYO | AB15: Centro de Referencia de Salud (CRS)
AA16: JUNIO | AB16: Consultorio General Urbano (CGU)
B17: SERIE A | G17: ESTADO MACROS: | AA17: JULIO | AB17: Consultorio General Urbano (CGU) - CESFAM
I18: HABILITADO | AA18: AGOSTO | AB18: Consultorio General Urbano(CGU) con SAPU/SUR/SAR
AA19: SEPTIEMBRE | AB19: Consultorio General Urbano (CGU) - CESFAM con SAPU/SAR
AA20: OCTUBRE | AB20: Consultorio General Rural (CGR)
AA21: NOVIEMBRE | AB21: Consultorio General Rural (CGR) - CESFAM
AA22: DICIEMBRE | AB22: Consultorio General Rural (CGR) con SAPU/SAR/SUR
AB23: Consultorio General Rural (CGR) - CESFAM con SAPU/SAR/SUR
AB24: Posta de Salud Rural (PSR)
AB25: Centro Comunitario de Salud Familiar (CECOF)
AB26: Consultorio de Salud Mental (COSAM)
AB27: Programa de Reparación y Atención Integral de Salud (PRAIS)
AB28: Centro de Atención Funcionarios (CAF)
AB29: Clínica Dental Móvil (CDM)
AB30: Dirección Servicio de Salud (DSS)
AB31: Servicio de Atención Primaria de Urgencia (SAPU)
AB32: SAPU Alta Resolución (SAR)
AB33: Laboratorio Clínico o Dental
AB34: Servicio de Atención Primaria de Urgencia Dental (SAPUDENT)
... AB37: Centro Oncologico

Sheet A01
B1: SERVICIO DE SALUD
B2: =CONCATENATE("COMUNA: ",NOMBRE!B2," - ","( ",NOMBRE!C2,NOMBRE!D2,NOMBRE!E2,NOMBRE!F2,NOMBRE!G2," )") -> COMUNA: - ( )
B3: =CONCATENATE("ESTABLECIMIENTO/ESTRATEGIA: ",NOMBRE!B3," - ","( ",NOMBRE!C3,NOMBRE!D3,NOMBRE!E3,NOMBRE!F3,NOMBRE!G3,NOMBRE!H3," )") -> ESTABLECIMIENTO/ESTRATEGIA: - ( )
B4: =CONCATENATE("MES: ",NOMBRE!B6," - ","( ",NOMBRE!C6,NOMBRE!D6," )") -> MES: - ( )
B5: =CONCATENATE("AÑO: ",NOMBRE!B7) -> AÑO: 2020
B6: REM-A01. CONTROLES DE SALUD
B9: SECCIÓN A: CONTROLES DE SALUD SEXUAL Y REPRODUCTIVA
B10: TIPO DE CONTROL | C10: PROFESIONAL | D10: TOTAL | E10: POR EDAD | U10: SEXO | W10: Beneficiarios | X10: Control con pareja familiar u otro | Y10: Control de diada con presencia del padre | Z10: TIPOS DE LACTANCIA
A11: CODIGO DICCIONARIO | E11: 5 - 9 | F11: 10 - 14 | G11: 15 a 19 | H11: 20 - 24 | I11: 25 - 29 | J11: 30 - 34 | K11: 35 - 39 | L11: 40 - 44 | M11: 45 - 49 | N11: 50 - 54 | O11: 55 - 59 | P11: 60 - 64 | Q11: 65 - 69 | R11: 70 - 74 | S11: 75 - 79 | T11: 80 y mas | U11: HOMBRES | V11: MUJERES | Z11: Lactancia Materna Exclusiva | AA11: Lactancia Materna / Formula Láctea | AB11: Formula Láctea
A12: 01010101 | B12: PRE- CONCEPCIONAL | C12: MÉDICO | D12: COL01 | E12: COL02 | F12: COL03 | G12: COL04 | H12: COL05 | I12: COL06 | J12: COL07 | K12: COL08 | L12: COL09 | M12: COL10 | N12: COL11 | O12: COL12 | P12: COL13 | Q12: COL14 | R12: COL15 | S12: COL16 | T12: COL17 | U12: COL18 | V12: COL19 | W12: COL20 | X12: COL21 | Y12: COL22 | Z12: COL23 | AA12: COL24 | AB12: COL25 | CM12: 0 | CN12: 0 | CR12: 0
A13: 01010103 | C13: MATRONA /ÓN | D13: COL01 | E13: COL02 | F13: COL03 | G13: COL04 | H13: COL05 | I13: COL06 | J13: COL07 | K13: COL08 | L13: COL09 | M13: COL10 | N13: COL11 | O13: COL12 | P13: COL13 | Q13: COL14 | R13: COL15 | S13: COL16 | T13: COL17 | U13: COL18 | V13: COL19 | W13: COL20 | X13: COL21 | Y13: COL22 | Z13: COL23 | AA13: COL24 | AB13: COL25 | CM13: 0 | CN13: 0 | CR13: 0
A14: 01010201 | B14: PRENATAL | C14: MÉDICO | D14: COL01 | E14: COL02 | F14: COL03 | G14: COL04 | H14: COL05 | I14: COL06 | J14: COL07 | K14: COL08 | L14: COL09 | M14: COL10 | N14: COL11 | O14: COL12 | P14: COL13 | Q14: COL14 | R14: COL15 | S14: COL16 | T14: COL17 | U14: COL18 | V14: COL19 | W14: COL20 | X14: COL21 | Y14: COL22 | Z14: COL23 | AA14: COL24 | AB14: COL25 | CM14: 0 | CN14: 0 | CO14: 0 | CR14: 0 | CS14: 0
A15: 01010203 | C15: MATRONA /ÓN | D15: COL01 | E15: COL02 | F15: COL03 | G15: COL04 | H15: COL05 | I15: COL06 | J15: COL07 | K15: COL08 | L15: COL09 | M15: COL10 | N15: COL11 | O15: COL12 | P15: COL13 | Q15: COL14 | R15: COL15 | S15: COL16 | T15: COL17 | U15: COL18 | V15: COL19 | W15: COL20 | X15: COL21 | Y15: COL22 | Z15: COL23 | AA15: COL24 | AB15: COL25 | CM15: 0 | CN15: 0 | CO15: 0 | CR15: 0 | CS15: 0
A16: 01080001 | B16: POST PARTO Y POST ABORTO | C16: MÉDICO | D16: COL01 | E16: COL02 | F16: COL03 | G16: COL04 | H16: COL05 | I16: COL06 | J16: COL07 | K16: COL08 | L16: COL09 | M16: COL10 | N16: COL11 | O16: COL12 | P16: COL13 | Q16: COL14 | R16: COL15 | S16: COL16 | T16: COL17 | U16: COL18 | V16: COL19 | W16: COL20 | X16: COL21 | Y16: COL22 | Z16: COL23 | AA16: COL24 | AB16: COL25 | CM16: 0 | CN16: 0 | CR16: 0
A17: 01080002 | C17: MATRONA /ÓN | D17: COL01 | E17: COL02 | F17: COL03 | G17: COL04 | H17: COL05 | I17: COL06 | J17: COL07 | K17: COL08 | L17: COL09 | M17: COL10 | N17: COL11 | O17: COL12 | P17: COL13 | Q17: COL14 | R17: COL15 | S17: COL16 | T17: COL17 | U17: COL18 | V17: COL19 | W17: COL20 | X17: COL21 | Y17: COL22 | Z17: COL23 | AA17: COL24 | AB17: COL25 | CM17: 0 | CN17: 0 | CR17: 0
A18: 01110106 | B18: PUÉRPERA CON RECIÉN NACIDO HASTA 10 DÍAS DE VIDA | C18: MÉDICO | D18: COL01 | E18: COL02 | F18: COL03 | G18: COL04 | H18: COL05 | I18: COL06 | J18: COL07 | K18: COL08 | L18: COL09 | M18: COL10 | N18: COL11 | O18: COL12 | P18: COL13 | Q18: COL14 | R18: COL15 | S18: COL16 | T18: COL17 | U18: COL18 | V18: COL19 | W18: COL20 | X18: COL21 | Y18: COL22 | Z18: COL23 | AA18: COL24 | AB18: COL25 | CG18: =IF(AND(D18<>0,'A05'!D50=""),"* No olvide registrar ingresos a control de salud de los respectivos RN, en REM A05-secci„n E. ","") | CM18: 0 | CN18: 0 | CP18: 0 | CQ18: 0 | CR18: 0 | CT18: 0 | CU18: 0
A19: 01110107 | C19: MATRONA /ÓN | D19: COL01 | E19: COL02 | F19: COL03 | G19: COL04 | H19: COL05 | I19: COL06 | J19: COL07 | K19: COL08 | L19: COL09 | M19: COL10 | N19: COL11 | O19: COL12 | P19: COL13 | Q19: COL14 | R19: COL15 | S19: COL16 | T19: COL17 | U19: COL18 | V19: COL19 | W19: COL20 | X19: COL21 | Y19: COL22 | Z19: COL23 | AA19: COL24 | AB19: COL25 | CG19: =IF(AND(D19<>0,'A05'!D50=""),"* No olvide registrar ingresos a control de salud de los respectivos RN, en REM A05-secci„n E. ","") | CM19: 0 | CN19: 0 | CP19: 0 | CQ19: 0 | CR19: 0 | CT19: 0 | CU19: 0
A20: 01080030 | B20: PUÉRPERA CON RECIÉN NACIDO ENTRE 11 y 28 DÍAS | C20: MÉDICO | D20: COL01 | E20: COL02 | F20: COL03 | G20: COL04 | H20: COL05 | I20: COL06 | J20: COL07 | K20: COL08 | L20: COL09 | M20: COL10 | N20: COL11 | O20: COL12 | P20: COL13 | Q20: COL14 | R20: COL15 | S20: COL16 | T20: COL17 | U20: COL18 | V20: COL19 | W20: COL20 | X20: COL21 | Y20: COL22 | Z20: COL23 | AA20: COL24 | AB20: COL25 | CG20: =IF(AND(D20<>0,'A05'!D50=""),"* No olvide registrar ingresos a control de salud de los respectivos RN, en REM A05-secci„n E. ","") | CM20: 0 | CN20: 0 | CP20: 0 | CQ20: 0 | CR20: 0 | CT20: 0 | CU20: 0
A21: 01080040 | C21: MATRONA /ÓN | D21: COL01 | E21: COL02 | F21: COL03 | G21: COL04 | H21: COL05 | I21: COL06 | J21: COL07 | K21: COL08 | L21: COL09 | M21: COL10 | N21: COL11 | O21: COL12 | P21: COL13 | Q21: COL14 | R21: COL15 | S21: COL16 | T21: COL17 | U21: COL18 | V21: COL19 | W21: COL20 | X21: COL21 | Y21: COL22 | Z21: COL23 | AA21: COL24 | AB21: COL25 | CG21: =IF(AND(D21<>0,'A05'!D50=""),"* No olvide registrar ingresos a control de salud de los respectivos RN, en REM A05-secci„n E. ","") | CM21: 0 | CN21: 0 | CP21: 0 | CQ21: 0 | CR21: 0 | CT21: 0 | CU21: 0
A22: 01010601 | B22: GINECOLÓGICO | C22: MÉDICO | D22: COL01 | E22: COL02 | F22: COL03 | G22: COL04 | H22: COL05 | I22: COL06 | J22: COL07 | K22: COL08 | L22: COL09 | M22: COL10 | N22: COL11 | O22: COL12 | P22: COL13 | Q22: COL14 | R22: COL15 | S22: COL16 | T22: COL17 | U22: COL18 | V22: COL19 | W22: COL20 | X22: COL21 | Y22: COL22 | Z22: COL23 | AA22: COL24 | AB22: COL25 | CM22: 0 | CN22: 0 | CR22: 0
A23: 01010603 | C23: MATRONA /ÓN | D23: COL01 | E23: COL02 | F23: COL03 | G23: COL04 | H23: COL05 | I23: COL06 | J23: COL07 | K23: COL08 | L23: COL09 | M23: COL10 | N23: COL11 | O23: COL12 | P23: COL13 | Q23: COL14 | R23: COL15 | S23: COL16 | T23: COL17 | U23: COL18 | V23: COL19 | W23: COL20 | X23: COL21 | Y23: COL22 | Z23: COL23 | AA23: COL24 | AB23: COL25 | CM23: 0 | CN23: 0 | CR23: 0
A24: 01010901 | B24: CLIMATERIO | C24: MÉDICO | D24: COL01 | E24: COL02 | F24: COL03 | G24: COL04 | H24: COL05 | I24: COL06 | J24: COL07 | K24: COL08 | L24: COL09 | M24: COL10 | N24: COL11 | O24: COL12 | P24: COL13 | Q24: COL14 | R24: COL15 | S24: COL16 | T24: COL17 | U24: COL18 | V24: COL19 | W24: COL20 | X24: COL21 | Y24: COL22 | Z24: COL23 | AA24: COL24 | AB24: COL25 | CM24: 0 | CN24: 0 | CR24: 0
A25: 01010903 | C25: MATRONA /ÓN | D25: COL01 | E25: COL02 | F25: COL03 | G25: COL04 | H25: COL05 | I25: COL06 | J25: COL07 | K25: COL08 | L25: COL09 | M25: COL10 | N25: COL11 | O25: COL12 | P25: COL13 | Q25: COL14 | R25: COL15 | S25: COL16 | T25: COL17 | U25: COL18 | V25: COL19 | W25: COL20 | X25: COL21 | Y25: COL22 | Z25: COL23 | AA25: COL24 | AB25: COL25 | CM25: 0 | CN25: 0 | CR25: 0
A26: 01010401 | B26: REGULACIÓN DE FECUNDIDAD | C26: MÉDICO | D26: COL01 | E26: COL02 | F26: COL03 | G26: COL04 | H26: COL05 | I26: COL06 | J26: COL07 | K26: COL08 | L26: COL09 | M26: COL10 | N26: COL11 | O26: COL12 | P26: COL13 | Q26: COL14 | R26: COL15 | S26: COL16 | T26: COL17 | U26: COL18 | V26: COL19 | W26: COL20 | X26: COL21 | Y26: COL22 | Z26: COL23 | AA26: COL24 | AB26: COL25 | CM26: 0 | CN26: 0 | CR26: 0
A27: 01010403 | C27: MATRONA /ÓN | D27: COL01 | E27: COL02 | F27: COL03 | G27: COL04 | H27: COL05 | I27: COL06 | J27: COL07 | K27: COL08 | L27: COL09 | M27: COL10 | N27: COL11 | O27: COL12 | P27: COL13 | Q27: COL14 | R27: COL15 | S27: COL16 | T27: COL17 | U27: COL18 | V27: COL19 | W27: COL20 | X27: COL21 | Y27: COL22 | Z27: COL23 | AA27: COL24 | AB27: COL25 | CM27: 0 | CN27: 0 | CR27: 0
B28: SECCIÓN B: CONTROLES DE SALUD SEGÚN CICLO VITAL
B29: TIPO DE CONTROL | C29: PROFESIONAL | D29: TOTAL | G29: POR EDAD | AJ29: Beneficiarios | AK29: CONTROL CON PRESENCIA DEL PADRE | AM29: Niños, Niñas, Adolescentes y Jóvenes Población SENAME
D30: Ambos Sexos | E30: Hombres | F30: Mujeres | G30: Menor de 1 mes | H30: 1 mes | I30: 2 meses | J30: 3 meses | K30: 4 meses | L30: 5 meses | M30: 6 meses | N30: 7 - 11 meses | O30: 12 a 17 meses | P30: 18 - 23 meses | Q30: 24 - 47 meses | R30: 48 - 59 meses | S30: 60 - 71 meses | T30: 6 - 9 | U30: 10 - 14 | V30: 15 - 19 | W30: 20 - 24 | X30: 25 - 29 | Y30: 30 - 34 | Z30: 35 - 39 | AA30: 40 - 44 | AB30: 45 - 49 | AC30: 50 - 54 | AD30: 55 - 59 | AE30: 60 - 64 | AF30: 65 - 69 | AG30: 70 - 74 | AH30: 75 - 79 | AI30: 80 y mas | AK30: menor 1 año | AL30: 1 año a 3 años 11 meses 29 días
A31: 02010101 | B31: DE SALUD | C31: MÉDICO | D31: COL01 | E31: COL02 | F31: COL03 | G31: COL04 | H31: COL05 | I31: COL06 | J31: COL07 | K31: COL08 | L31: COL09 | M31: COL10 | N31: COL11 | O31: COL12 | P31: COL13 | Q31: COL14 | R31: COL15 | S31: COL16 | T31: COL17 | U31: COL18 | V31: COL19 | W31: COL20 | X31: COL21 | Y31: COL22 | Z31: COL23 | AA31: COL24 | AB31: COL25 | AC31: COL26 | AD31: COL27 | AE31: COL28 | AF31: COL29 | AG31: COL30 | AH31: COL31 | AI31: COL32 | AJ31: COL33 | AK31: COL34 | AL31: COL35 | AM31: COL36 | CD31: =IF(AK31>SUM(G31:N31),"* Los controles con presencia del padre NO DEBE ser mayor que el total Controles Menor 1 año. ",IF(AL31>SUM(O31:Q31),"* Los controles con presencia del padre NO DEBE ser mayor que el total Controles 1 año a 3 años 11 meses 29 dÍas. ","")) -> * Los controles con presencia del padre NO DEBE ser mayor que el total Controles Menor 1 año. | CE31: =IF(AND(G31<>0,'A05'!D50=""),"* NO OLVIDE REGISTRAR INGRESOS A CONTROL DE SALUD DE LOS RESPECTIVOS RN, EN REM A05-SECCIÓN E. ","") | CI31: 0 | CJ31: =IF(AK31>SUM(G31:N31),1,IF(AL31>SUM(O31:Q31),1,0)) -> 1 | CK31: 0
A32: 02010201 | C32: ENFERMERA /O | D32: COL01 | E32: COL02 | F32: COL03 | G32: COL04 | H32: COL05 | I32: COL06 | J32: COL07 | K32: COL08 | L32: COL09 | M32: COL10 | N32: COL11 | O32: COL12 | P32: COL13 | Q32: COL14 | R32: COL15 | S32: COL16 | T32: COL17 | U32: COL18 | V32: COL19 | W32: COL20 | X32: COL21 | Y32: COL22 | Z32: COL23 | AA32: COL24 | AB32: COL25 | AC32: COL26 | AD32: COL27 | AE32: COL28 | AF32: COL29 | AG32: COL30 | AH32: COL31 | AI32: COL32 | AJ32: COL33 | AK32: COL34 | AL32: COL35 | AM32: COL36 | CD32: =IF(AK32>SUM(G32:N32),"* Los controles con presencia del padre NO DEBE ser mayor que el total Controles Menor 1 año. ",IF(AL32>SUM(O32:Q32),"* Los controles con presencia del padre NO DEBE ser mayor que el total Controles 1 año a 3 años 11 meses 29 dÍas. ","")) -> * Los controles con presencia del padre NO DEBE ser mayor que el total Controles Menor 1 año. | CE32: =IF(AND(G32<>0,'A05'!D50=""),"* NO OLVIDE REGISTRAR INGRESOS A CONTROL DE SALUD DE LOS RESPECTIVOS RN, EN REM A05-SECCIÓN E. ","") | CI32: 0 | CJ32: =IF(AK32>SUM(G32:N32),1,IF(AL32>SUM(O32:Q32),1,0)) -> 1 | CK32: 0
A33: 02010103 | C33: MATRONA /ÓN | D33: COL01 | E33: COL02 | F33: COL03 | G33: COL04 | H33: COL05 | I33: COL06 | J33: COL07 | K33: COL08 | L33: COL09 | M33: COL10 | N33: COL11 | O33: COL12 | P33: COL13 | Q33: COL14 | R33: COL15 | S33: COL16 | T33: COL17 | U33: COL18 | V33: COL19 | W33: COL20 | X33: COL21 | Y33: COL22 | Z33: COL23 | AA33: COL24 | AB33: COL25 | AC33: COL26 | AD33: COL27 | AE33: COL28 | AF33: COL29 | AG33: COL30 | AH33: COL31 | AI33: COL32 | AJ33: COL33 | AK33: COL34 | AL33: COL35 | AM33: COL36 | CD33: =IF((AK33>G33),"* Los controles con presencia del padre NO DEBE ser mayor que el total Controles Menor 1 año. ","") -> * Los controles con presencia del padre NO DEBE ser mayor que el total Controles Menor 1 año. | CE33: =IF(AND(G33<>0,'A05'!D50=""),"* NO OLVIDE REGISTRAR INGRESOS A CONTROL DE SALUD DE LOS RESPECTIVOS RN, EN REM A05-SECCIÓN E. ","") | CI33: 0 | CJ33: =IF(AK33>SUM(G33:N33),1,IF(AL33>SUM(O33:Q33),1,0)) -> 1 | CK33: 0
A34: 02010105 | C34: TÉCNICO PARAMÉDICO | D34: COL01 | E34: COL02 | F34: COL03 | G34: COL04 | H34: COL05 | I34: COL06 | J34: COL07 | K34: COL08 | L34: COL09 | M34: COL10 | N34: COL11 | O34: COL12 | P34: COL13 | Q34: COL14 | R34: COL15 | S34: COL16 | T34: COL17 | U34: COL18 | V34: COL19 | W34: COL20 | X34: COL21 | Y34: COL22 | Z34: COL23 | AA34: COL24 | AB34: COL25 | AC34: COL26 | AD34: COL27 | AE34: COL28 | AF34: COL29 | AG34: COL30 | AH34: COL31 | AI34: COL32 | AJ34: COL33 | AK34: COL34 | AL34: COL35 | AM34: COL36 | CD34: =IF(AL34>SUM(O34:T34),"* Los controles con presencia del padre NO DEBE ser mayor que el total Controles 1año a 3 años 11 meses 29 dÍas. ","") -> * Los controles con presencia del padre NO DEBE ser mayor que el total Controles 1año a 3 años 11 meses 29 dÍas. | CI34: 0 | CJ34: =IF(AK34>SUM(G34:N34),1,IF(AL34>SUM(O34:Q34),1,0)) -> 1 | CK34: 0
B35: SECCIÓN C: CONTROLES SEGÚN PROBLEMA DE SALUD
B36: TIPO DE CONTROL | C36: PROFESIONAL | D36: TOTAL | G36: POR EDAD | AO36: Beneficiarios
G37: 0 - 4 | I37: 5 - 9 | K37: 10 - 14 | M37: 15 a 19 | O37: 20 - 24 | Q37: 25 - 29 | S37: 30 - 34 | U37: 35 - 39 | W37: 40 - 44 | Y37: 45 - 49 | AA37: 50 - 54 | AC37: 55 - 59 | AE37: 60 - 64 | AG37: 65 - 69 | AI37: 70 - 74 | AK37: 75 - 79 | AM37: 80 y mas
D38: Ambos Sexos | E38: Hombres | F38: Mujeres | G38: Hombres | H38: Mujeres | I38: Hombres | J38: Mujeres | K38: Hombres | L38: Mujeres | M38: Hombres | N38: Mujeres | O38: Hombres | P38: Mujeres | Q38: Hombres | R38: Mujeres | S38: Hombres | T38: Mujeres | U38: Hombres | V38: Mujeres | W38: Hombres | X38: Mujeres | Y38: Hombres | Z38: Mujeres | AA38: Hombres | AB38: Mujeres | AC38: Hombres | AD38: Mujeres | AE38: Hombres | AF38: Mujeres | AG38: Hombres | AH38: Mujeres | AI38: Hombres | AJ38: Mujeres | AK38: Hombres | AL38: Mujeres | AM38: Hombres | AN38: Mujeres
A39: 03010501 | B39: DE SALUD CARDIOVASCULAR | C39: MÉDICO | D39: COL01 | E39: COL02 | F39: COL03 | G39: COL04 | H39: COL05 | I39: COL06 | J39: COL07 | K39: COL08 | L39: COL09 | M39: COL10 | N39: COL11 | O39: COL12 | P39: COL13 | Q39: COL14 | R39: COL15 | S39: COL16 | T39: COL17 | U39: COL18 | V39: COL19 | W39: COL20 | X39: COL21 | Y39: COL22 | Z39: COL23 | AA39: COL24 | AB39: COL25 | AC39: COL26 | AD39: COL27 | AE39: COL28 | AF39: COL29 | AG39: COL30 | AH39: COL31 | AI39: COL32 | AJ39: COL33 | AK39: COL34 | AL39: COL35 | AM39: COL36 | AN39: COL37 | AO39: COL38 | CJ39: 0
A40: 03010502 | C40: ENFERMERA /O | D40: COL01 | E40: COL02 | F40: COL03 | G40: COL04 | H40: COL05 | I40: COL06 | J40: COL07 | K40: COL08 | L40: COL09 | M40: COL10 | N40: COL11 | O40: COL12 | P40: COL13 | Q40: COL14 | R40: COL15 | S40: COL16 | T40: COL17 | U40: COL18 | V40: COL19 | W40: COL20 | X40: COL21 | Y40: COL22 | Z40: COL23 | AA40: COL24 | AB40: COL25 | AC40: COL26 | AD40: COL27 | AE40: COL28 | AF40: COL29 | AG40: COL30 | AH40: COL31 | AI40: COL32 | AJ40: COL33 | AK40: COL34 | AL40: COL35 | AM40: COL36 | AN40: COL37 | AO40: COL38 | CJ40: 0
A41: 03010504 | C41: NUTRICIONISTA | D41: COL01 | E41: COL02 | F41: COL03 | G41: COL04 | H41: COL05 | I41: COL06 | J41: COL07 | K41: COL08 | L41: COL09 | M41: COL10 | N41: COL11 | O41: COL12 | P41: COL13 | Q41: COL14 | R41: COL15 | S41: COL16 | T41: COL17 | U41: COL18 | V41: COL19 | W41: COL20 | X41: COL21 | Y41: COL22 | Z41: COL23 | AA41: COL24 | AB41: COL25 | AC41: COL26 | AD41: COL27 | AE41: COL28 | AF41: COL29 | AG41: COL30 | AH41: COL31 | AI41: COL32 | AJ41: COL33 | AK41: COL34 | AL41: COL35 | AM41: COL36 | AN41: COL37 | AO41: COL38 | CJ41: 0
A42: 03010505 | C42: TÉCNICO PARAMÉDICO | D42: COL01 | E42: COL02 | F42: COL03 | G42: COL04 | H42: COL05 | I42: COL06 | J42: COL07 | K42: COL08 | L42: COL09 | M42: COL10 | N42: COL11 | O42: COL12 | P42: COL13 | Q42: COL14 | R42: COL15 | S42: COL16 | T42: COL17 | U42: COL18 | V42: COL19 | W42: COL20 | X42: COL21 | Y42: COL22 | Z42: COL23 | AA42: COL24 | AB42: COL25 | AC42: COL26 | AD42: COL27 | AE42: COL28 | AF42: COL29 | AG42: COL30 | AH42: COL31 | AI42: COL32 | AJ42: COL33 | AK42: COL34 | AL42: COL35 | AM42: COL36 | AN42: COL37 | AO42: COL38 | CJ42: 0
...

Sheet A02
B1: SERVICIO DE SALUD
B2: =CONCATENATE("COMUNA: ",NOMBRE!B2," - ","( ",NOMBRE!C2,NOMBRE!D2,NOMBRE!E2,NOMBRE!F2,NOMBRE!G2," )") -> COMUNA: - ( )
B3: =CONCATENATE("ESTABLECIMIENTO/ESTRATEGIA: ",NOMBRE!B3," - ","( ",NOMBRE!C3,NOMBRE!D3,NOMBRE!E3,NOMBRE!F3,NOMBRE!G3,NOMBRE!H3," )") -> ESTABLECIMIENTO/ESTRATEGIA: - ( )
B4: =CONCATENATE("MES: ",NOMBRE!B6," - ","( ",NOMBRE!C6,NOMBRE!D6," )") -> MES: - ( )
B5: =CONCATENATE("AÑO: ",NOMBRE!B7) -> AÑO: 2020
B6: REM-A02. EXAMEN DE MEDICINA PREVENTIVA EN MAYORES DE 15 AÑOS
B8: SECCIÓN A: EMP REALIZADO POR PROFESIONAL
A9: CODIGO DICCIONARIO | B9: PROFESIONAL | C9: TOTAL
C10: Ambos Sexos | D10: Hombres | E10: Mujeres
B11: TOTAL | C11: =SUM(C12:C17) -> 0 | D11: =SUM(D12:D17) -> 0 | E11: =SUM(E12:E17) -> 0
A12: 03030101 | B12: MÉDICO | C12: COL01 | D12: COL02 | E12: COL03
A13: 03030102 | B13: ENFERMERA /O | C13: COL01 | D13: COL02 | E13: COL03
A14: 03030103 | B14: MATRONA /ÓN | C14: COL01 | D14: COL02 | E14: COL03
A15: 03030104 | B15: NUTRICIONISTA | C15: COL01 | D15: COL02 | E15: COL03
A16: 03030350 | B16: OTRO PROFESIONAL | C16: COL01 | D16: COL02 | E16: COL03
A17: 03030110 | B17: TÉCNICO PARAMÉDICO | C17: COL01 | D17: COL02 | E17: COL03
B18: SECCIÓN B: EMP SEGÚN RESULTADO DEL ESTADO NUTRICIONAL
B19: ESTADO NUTRICIONAL | C19: TOTAL | F19: 15 a 19 | H19: 20 a 24 | J19: 25 a 29 | L19: 30 a 34 | N19: 35 a 39 | P19: 40 a 44 | R19: 45 a 49 | T19: 50 a 54 | V19: 55 a 59 | X19: 60 a 64 | Z19: 65 a 69 | AB19: 70 a 74 | AD19: 75 a 79 | AF19: 80 y más
C20: Ambos Sexos | D20: Hombres | E20: Mujeres | F20: Hombres | G20: Mujeres | H20: Hombres | I20: Mujeres | J20: Hombres | K20: Mujeres | L20: Hombres | M20: Mujeres | N20: Hombres | O20: Mujeres | P20: Hombres | Q20: Mujeres | R20: Hombres | S20: Mujeres | T20: Hombres | U20: Mujeres | V20: Hombres | W20: Mujeres | X20: Hombres | Y20: Mujeres | Z20: Hombres | AA20: Mujeres | AB20: Hombres | AC20: Mujeres | AD20: Hombres | AE20: Mujeres | AF20: Hombres | AG20: Mujeres
B21: TOTAL | C21: =SUM(C22:C25) -> 0 | D21: =SUM(D22:D25) -> 0 | E21: =SUM(E22:E25) -> 0 | F21: =SUM(F22:F25) -> 0 | G21: =SUM(G22:G25) -> 0 | H21: =SUM(H22:H25) -> 0 | I21: =SUM(I22:I25) -> 0 | J21: =SUM(J22:J25) -> 0 | ... AG21: =SUM(AG22:AG25) -> 0 | CJ21: 0
A22: 03030330 | B22: NORMAL | C22: COL01 | D22: COL02 | E22: COL03 | F22: COL04 | G22: COL05 | H22: COL06 | I22: COL07 | J22: COL08 | K22: COL09 | L22: COL10 | M22: COL11 | N22: COL12 | O22: COL13 | P22: COL14 | Q22: COL15 | R22: COL16 | S22: COL17 | T22: COL18 | U22: COL19 | V22: COL20 | W22: COL21 | X22: COL22 | Y22: COL23 | Z22: COL24 | AA22: COL25 | AB22: COL26 | AC22: COL27 | AD22: COL28 | AE22: COL29 | AF22: COL30 | AG22: COL31
A23: 03030340 | B23: BAJO PESO | C23: COL01 | D23: COL02 | E23: COL03 | F23: COL04 | G23: COL05 | H23: COL06 | I23: COL07 | J23: COL08 | K23: COL09 | L23: COL10 | M23: COL11 | N23: COL12 | O23: COL13 | P23: COL14 | Q23: COL15 | R23: COL16 | S23: COL17 | T23: COL18 | U23: COL19 | V23: COL20 | W23: COL21 | X23: COL22 | Y23: COL23 | Z23: COL24 | AA23: COL25 | AB23: COL26 | AC23: COL27 | AD23: COL28 | AE23: COL29 | AF23: COL30 | AG23: COL31
A24: 03030120 | B24: SOBREPESO | C24: COL01 | D24: COL02 | E24: COL03 | F24: COL04 | G24: COL05 | H24: COL06 | I24: COL07 | J24: COL08 | K24: COL09 | L24: COL10 | M24: COL11 | N24: COL12 | O24: COL13 | P24: COL14 | Q24: COL15 | R24: COL16 | S24: COL17 | T24: COL18 | U24: COL19 | V24: COL20 | W24: COL21 | X24: COL22 | Y24: COL23 | Z24: COL24 | AA24: COL25 | AB24: COL26 | AC24: COL27 | AD24: COL28 | AE24: COL29 | AF24: COL30 | AG24: COL31
A25: 03030130 | B25: OBESOS | C25: COL01 | D25: COL02 | E25: COL03 | F25: COL04 | G25: COL05 | H25: COL06 | I25: COL07 | J25: COL08 | K25: COL09 | L25: COL10 | M25: COL11 | N25: COL12 | O25: COL13 | P25: COL14 | Q25: COL15 | R25: COL16 | S25: COL17 | T25: COL18 | U25: COL19 | V25: COL20 | W25: COL21 | X25: COL22 | Y25: COL23 | Z25: COL24 | AA25: COL25 | AB25: COL26 | AC25: COL27 | AD25: COL28 | AE25: COL29 | AF25: COL30 | AG25: COL31
B26: SECCIÓN C: RESULTADOS DE EMP SEGÚN ESTADO DE SALUD
B27: ESTADO DE SALUD | C27: TOTAL | F27: 15 a 19 | H27: 20 a 24 | J27: 25 a 29 | L27: 30 a 34 | N27: 35 a 39 | P27: 40 a 44 | R27: 45 a 49 | T27: 50 a 54 | V27: 55 a 59 | X27: 60 a 64 | Z27: 65 a 69 | AB27: 70 a 74 | AD27: 75 a 79 | AF27: 80 y más
C28: Ambos Sexos | D28: Hombres | E28: Mujeres | F28: Hombres | G28: Mujeres | H28: Hombres | I28: Mujeres | J28: Hombres | K28: Mujeres | L28: Hombres | M28: Mujeres | N28: Hombres | O28: Mujeres | P28: Hombres | Q28: Mujeres | R28: Hombres | S28: Mujeres | T28: Hombres | U28: Mujeres | V28: Hombres | W28: Mujeres | X28: Hombres | Y28: Mujeres | Z28: Hombres | AA28: Mujeres | AB28: Hombres | AC28: Mujeres | AD28: Hombres | AE28: Mujeres | AF28: Hombres | AG28: Mujeres
A29: 02200010 | B29: TABAQUISMO | C29: COL01 | D29: COL02 | E29: COL03 | F29: COL04 | G29: COL05 | H29: COL06 | I29: COL07 | J29: COL08 | K29: COL09 | L29: COL10 | M29: COL11 | N29: COL12 | O29: COL13 | P29: COL14 | Q29: COL15 | R29: COL16 | S29: COL17 | T29: COL18 | U29: COL19 | V29: COL20 | W29: COL21 | X29: COL22 | Y29: COL23 | Z29: COL24 | AA29: COL25 | AB29: COL26 | AC29: COL27 | AD29: COL28 | AE29: COL29 | AF29: COL30 | AG29: COL31 | CH29: 0
A30: 02200020 | B30: PRESIÓN ARTERIAL ELEVADA (= >140/90 mmHg) | C30: COL01 | D30: COL02 | E30: COL03 | F30: COL04 | G30: COL05 | H30: COL06 | I30: COL07 | J30: COL08 | K30: COL09 | L30: COL10 | M30: COL11 | N30: COL12 | O30: COL13 | P30: COL14 | Q30: COL15 | R30: COL16 | S30: COL17 | T30: COL18 | U30: COL19 | V30: COL20 | W30: COL21 | X30: COL22 | Y30: COL23 | Z30: COL24 | AA30: COL25 | AB30: COL26 | AC30: COL27 | AD30: COL28 | AE30: COL29 | AF30: COL30 | AG30: COL31 | CH30: 0
B31: SECCIÓN D: RESULTADOS DE EMP SEGÚN ESTADO DE SALUD (EXÁMENES DE LABORATORIO)
B32: ESTADO DE SALUD | C32: TOTAL | F32: 15 a 19 años | H32: 20 a 24 años | J32: 25 a 29 | L32: 30 a 34 | N32: 35 a 39 | P32: 40 a 44 | R32: 45 a 49 | T32: 50 a 54 | V32: 55 a 59 | X32: 60 a 64 | Z32: 65 a 69 | AB32: 70 a 74 | AD32: 75 a 79 | AF32: 80 y más
C33: Ambos Sexos | D33: Hombres | E33: Mujeres | F33: Hombres | G33: Mujeres | H33: Hombres | I33: Mujeres | J33: Hombres | K33: Mujeres | L33: Hombres | M33: Mujeres | N33: Hombres | O33: Mujeres | P33: Hombres | Q33: Mujeres | R33: Hombres | S33: Mujeres | T33: Hombres | U33: Mujeres | V33: Hombres | W33: Mujeres | X33: Hombres | Y33: Mujeres | Z33: Hombres | AA33: Mujeres | AB33: Hombres | AC33: Mujeres | AD33: Hombres | AE33: Mujeres | AF33: Hombres | AG33: Mujeres
A34: 02200030 | B34: GLICEMIA ALTERADA (= > a 100 mg/dl) | C34: COL01 | D34: COL02 | E34: COL03 | F34: COL04 | G34: COL05 | H34: COL06 | I34: COL07 | J34: COL08 | K34: COL09 | L34: COL10 | M34: COL11 | N34: COL12 | O34: COL13 | P34: COL14 | Q34: COL15 | R34: COL16 | S34: COL17 | T34: COL18 | U34: COL19 | V34: COL20 | W34: COL21 | X34: COL22 | Y34: COL23 | Z34: COL24 | AA34: COL25 | AB34: COL26 | AC34: COL27 | AD34: COL28 | AE34: COL29 | AF34: COL30 | AG34: COL31
A35: 02200040 | B35: COLESTEROL ELEVADO (= > 200 mg/dl) | C35: COL01 | D35: COL02 | E35: COL03 | F35: COL04 | G35: COL05 | H35: COL06 | I35: COL07 | J35: COL08 | K35: COL09 | L35: COL10 | M35: COL11 | N35: COL12 | O35: COL13 | P35: COL14 | Q35: COL15 | R35: COL16 | S35: COL17 | T35: COL18 | U35: COL19 | V35: COL20 | W35: COL21 | X35: COL22 | Y35: COL23 | Z35: COL24 | AA35: COL25 | AB35: COL26 | AC35: COL27 | AD35: COL28 | AE35: COL29 | AF35: COL30 | AG35: COL31
B195: =SUM(C12:C17,C21:C25,C29:C30,C34:C35) -> 0 | C195: =SUM(CH7:CN52) -> 0

Sheet A03
B1: SERVICIO DE SALUD
B2: =CONCATENATE("COMUNA:",NOMBRE!B2," - ","( ",NOMBRE!C2,NOMBRE!D2,NOMBRE!E2,NOMBRE!F2,NOMBRE!G2," )") -> COMUNA: - ( )
B3: =CONCATENATE("ESTABLECIMIENTO/ESTRATEGIA: ",NOMBRE!B3," - ","( ",NOMBRE!C3,NOMBRE!D3,NOMBRE!E3,NOMBRE!F3,NOMBRE!G3,NOMBRE!H3," )") -> ESTABLECIMIENTO/ESTRATEGIA: - ( )
B4: =CONCATENATE("MES: ",NOMBRE!B6," - ","( ",NOMBRE!C6,NOMBRE!D6," )") -> MES: - ( )
B5: =CONCATENATE("AÑO: ",NOMBRE!B7) -> AÑO: 2020
B6: REM-A03. APLICACIÓN Y RESULTADOS DE ESCALAS DE EVALUACIÓN
B7: SECCIÓN A: APLICACIÓN DE INSTRUMENTO Y RESULTADO EN EL NIÑO (A)
B8: SECCIÓN A.1: APLICACIÓN Y RESULTADOS DE PAUTA BREVE
A9: CODIGO DICCIONARIO | B9: EVALUACIONES POR EDAD DEL NIÑO | D9: TOTAL | G9: GRUPO DE EDAD
G10: Menor de 1 mes | I10: 1 mes | K10: 2 meses | M10: 3 meses | O10: 4 meses | Q10: 5 meses | S10: 6 meses | U10: 7 - 11 meses | W10: 12 - 17 meses | Y10: 18 - 24 meses
D11: Ambos Sexos | E11: Hombres | F11: Mujeres | G11: Hombres | H11: Mujeres | I11: Hombres | J11: Mujeres | K11: Hombres | L11: Mujeres | M11: Hombres | N11: Mujeres | O11: Hombres | P11: Mujeres | Q11: Hombres | R11: Mujeres | S11: Hombres | T11: Mujeres | U11: Hombres | V11: Mujeres | W11: Hombres | X11: Mujeres | Y11: Hombres | Z11: Mujeres
A12: 02021730 | B12: APLICACIÓN PAUTA BREVE | D12: COL01 | E12: COL02 | F12: COL03 | G12: COL04 | H12: COL05 | I12: COL06 | J12: COL07 | K12: COL08 | L12: COL09 | M12: COL10 | N12: COL11 | O12: COL12 | P12: COL13 | Q12: COL14 | R12: COL15 | S12: COL16 | T12: COL17 | U12: COL18 | V12: COL19 | W12: COL20 | X12: COL21 | Y12: COL22 | Z12: COL23
A13: 03500020 | B13: RESULTADOS | C13: NORMAL | D13: COL01 | E13: COL02 | F13: COL03 | G13: COL04 | H13: COL05 | I13: COL06 | J13: COL07 | K13: COL08 | L13: COL09 | M13: COL10 | N13: COL11 | O13: COL12 | P13: COL13 | Q13: COL14 | R13: COL15 | S13: COL16 | T13: COL17 | U13: COL18 | V13: COL19 | W13: COL20 | X13: COL21 | Y13: COL22 | Z13: COL23 | DG13: 0 | DH13: 0 | DI13: 0 | DJ13: 0 | DK13: 0 | DL13: 0 | DM13: 0 | DN13: 0 | DO13: 0 | DP13: 0 | DQ13: 0 | DR13: 0 | DS13: 0 | DT13: 0 | DU13: 0 | DV13: 0 | DW13: 0 | DX13: 0 | DY13: 0 | DZ13: 0
A14: 03500030 | C14: ALTERADO | D14: COL01 | E14: COL02 | F14: COL03 | G14: COL04 | H14: COL05 | I14: COL06 | J14: COL07 | K14: COL08 | L14: COL09 | M14: COL10 | N14: COL11 | O14: COL12 | P14: COL13 | Q14: COL14 | R14: COL15 | S14: COL16 | T14: COL17 | U14: COL18 | V14: COL19 | W14: COL20 | X14: COL21 | Y14: COL22 | Z14: COL23
B16: SECCIÓN A.2: RESULTADOS DE LA APLICACIÓN DE ESCALA DE EVALUACIÓN DEL DESARROLLO PSICOMOTOR
B17: ACTIVIDAD | C17: RESULTADO | D17: TOTAL | G17: POR EDAD | S17: MIGRANTES
G18: Menor 7 meses | I18: 7 - 11 meses | K18: 12 - 17 meses | M18: 18 - 23 meses | O18: 24 - 47 meses | Q18: 48 - 59 meses
D19: Ambos Sexos | E19: Hombres | F19: Mujeres | G19: Hombres | H19: Mujeres | I19: Hombres | J19: Mujeres | K19: Hombres | L19: Mujeres | M19: Hombres | N19: Mujeres | O19: Hombres | P19: Mujeres | Q19: Hombres | R19: Mujeres
A20: 02021740 | B20: APLICACIÓN TEST DE DESARROLLO PSICOMOTOR | D20: COL01 | E20: COL02 | F20: COL03 | G20: COL04 | H20: COL05 | I20: COL06 | J20: COL07 | K20: COL08 | L20: COL09 | M20: COL10 | N20: COL11 | O20: COL12 | P20: COL13 | Q20: COL14 | R20: COL15 | S20: COL16 | CH20: 0 | CI20: 0 | CJ20: 0 | CK20: 0 | CL20: 0 | CM20: 0 | CN20: 0 | CO20: 0
A21: 02010320 | B21: PRIMERA EVALUACIÓN | C21: NORMAL | D21: COL01 | E21: COL02 | F21: COL03 | G21: COL04 | H21: COL05 | I21: COL06 | J21: COL07 | K21: COL08 | L21: COL09 | M21: COL10 | N21: COL11 | O21: COL12 | P21: COL13 | Q21: COL14 | R21: COL15 | S21: COL16
A22: 05225303 | C22: NORMAL CON REZAGO | D22: COL01 | E22: COL02 | F22: COL03 | G22: COL04 | H22: COL05 | I22: COL06 | J22: COL07 | K22: COL08 | L22: COL09 | M22: COL10 | N22: COL11 | O22: COL12 | P22: COL13 | Q22: COL14 | R22: COL15 | S22: COL16
A23: 02010321 | C23: RIESGO | D23: COL01 | E23: COL02 | F23: COL03 | G23: COL04 | H23: COL05 | I23: COL06 | J23: COL07 | K23: COL08 | L23: COL09 | M23: COL10 | N23: COL11 | O23: COL12 | P23: COL13 | Q23: COL14 | R23: COL15 | S23: COL16
A24: 02010322 | C24: RETRASO | D24: COL01 | E24: COL02 | F24: COL03 | G24: COL04 | H24: COL05 | I24: COL06 | J24: COL07 | K24: COL08 | L24: COL09 | M24: COL10 | N24: COL11 | O24: COL12 | P24: COL13 | Q24: COL14 | R24: COL15 | S24: COL16
A25: 05225304 | B25: REEVALUACIÓN | C25: NORMAL (desde normal con rezago) | D25: COL01 | E25: COL02 | F25: COL03 | G25: COL04 | H25: COL05 | I25: COL06 | J25: COL07 | K25: COL08 | L25: COL09 | M25: COL10 | N25: COL11 | O25: COL12 | P25: COL13 | Q25: COL14 | R25: COL15 | S25: COL16
A26: 02010420 | C26: NORMAL (desde riesgo) | D26: COL01 | E26: COL02 | F26: COL03 | G26: COL04 | H26: COL05 | I26: COL06 | J26: COL07 | K26: COL08 | L26: COL09 | M26: COL10 | N26: COL11 | O26: COL12 | P26: COL13 | Q26: COL14 | R26: COL15 | S26: COL16
A27: 05225305 | C27: NORMAL (desde retraso) | D27: COL01 | E27: COL02 | F27: COL03 | G27: COL04 | H27: COL05 | I27: COL06 | J27: COL07 | K27: COL08 | L27: COL09 | M27: COL10 | N27: COL11 | O27: COL12 | P27: COL13 | Q27: COL14 | R27: COL15 | S27: COL16
A28: 03500366 | C28: NORMAL CON REZAGO (desde riesgo) | D28: COL01 | E28: COL02 | F28: COL03 | G28: COL04 | H28: COL05 | I28: COL06 | J28: COL07 | K28: COL08 | L28: COL09 | M28: COL10 | N28: COL11 | O28: COL12 | P28: COL13 | Q28: COL14 | R28: COL15 | S28: COL16
A29: 03500400 | C29: NORMAL CON REZAGO (desde retraso) | D29: COL01 | E29: COL02 | F29: COL03 | G29: COL04 | H29: COL05 | I29: COL06 | J29: COL07 | K29: COL08 | L29: COL09 | M29: COL10 | N29: COL11 | O29: COL12 | P29: COL13 | Q29: COL14 | R29: COL15 | S29: COL16
A30: 03500401 | C30: RIESGO (desde retraso) | D30: COL01 | E30: COL02 | F30: COL03 | G30: COL04 | H30: COL05 | I30: COL06 | J30: COL07 | K30: COL08 | L30: COL09 | M30: COL10 | N30: COL11 | O30: COL12 | P30: COL13 | Q30: COL14 | R30: COL15 | S30: COL16
A31: 05225306 | C31: NORMAL CON REZAGO (desde normal con rezago) | D31: COL01 | E31: COL02 | F31: COL03 | G31: COL04 | H31: COL05 | I31: COL06 | J31: COL07 | K31: COL08 | L31: COL09 | M31: COL10 | N31: COL11 | O31: COL12 | P31: COL13 | Q31: COL14 | R31: COL15 | S31: COL16
A32: 02010421 | C32: RIESGO (desde riesgo) | D32: COL01 | E32: COL02 | F32: COL03 | G32: COL04 | H32: COL05 | I32: COL06 | J32: COL07 | K32: COL08 | L32: COL09 | M32: COL10 | N32: COL11 | O32: COL12 | P32: COL13 | Q32: COL14 | R32: COL15 | S32: COL16
A33: 02010422 | C33: RETRASO (desde retraso) | D33: COL01 | E33: COL02 | F33: COL03 | G33: COL04 | H33: COL05 | I33: COL06 | J33: COL07 | K33: COL08 | L33: COL09 | M33: COL10 | N33: COL11 | O33: COL12 | P33: COL13 | Q33: COL14 | R33: COL15 | S33: COL16
A34: 03500331 | B34: DERIVADOS A ESPECIALIDAD | C34: RIESGO | D34: COL01 | E34: COL02 | F34: COL03 | G34: COL04 | H34: COL05 | I34: COL06 | J34: COL07 | K34: COL08 | L34: COL09 | M34: COL10 | N34: COL11 | O34: COL12 | P34: COL13 | Q34: COL14 | R34: COL15 | S34: COL16
A35: 03500332 | C35: RETRASO | D35: COL01 | E35: COL02 | F35: COL03 | G35: COL04 | H35: COL05 | I35: COL06 | J35: COL07 | K35: COL08 | L35: COL09 | M35: COL10 | N35: COL11 | O35: COL12 | P35: COL13 | Q35: COL14 | R35: COL15 | S35: COL16
A36: 03500333 | B36: TRASLADO DE ESTABLECIMIENTO | C36: NORMAL CON REZAGO | D36: COL01 | E36: COL02 | F36: COL03 | G36: COL04 | H36: COL05 | I36: COL06 | J36: COL07 | K36: COL08 | L36: COL09 | M36: COL10 | N36: COL11 | O36: COL12 | P36: COL13 | Q36: COL14 | R36: COL15 | S36: COL16
A37: 03500334 | C37: RIESGO | D37: COL01 | E37: COL02 | F37: COL03 | G37: COL04 | H37: COL05 | I37: COL06 | J37: COL07 | K37: COL08 | L37: COL09 | M37: COL10 | N37: COL11 | O37: COL12 | P37: COL13 | Q37: COL14 | R37: COL15 | S37: COL16
A38: 03500335 | C38: RETRASO | D38: COL01 | E38: COL02 | F38: COL03 | G38: COL04 | H38: COL05 | I38: COL06 | J38: COL07 | K38: COL08 | L38: COL09 | M38: COL10 | N38: COL11 | O38: COL12 | P38: COL13 | Q38: COL14 | R38: COL15 | S38: COL16
B39: SECCIÓN A.3: NIÑOS Y NIÑAS CON REZAGO, DÉFICIT U OTRA VULNERABILIDAD DERIVADOS A ALGUNA MODALIDAD DE ESTIMULACIÓN EN LA PRIMERA EVALUACIÓN
B40: NIÑO / A | D40: TOTAL | G40: POR EDAD
G41: Menor 7 meses | I41: 7 - 11 meses | K41: 12 - 17 meses | M41: 18 - 23 meses | O41: 24 - 47 meses | Q41: 48 - 59 meses
...

Sheet A04
B1: SERVICIO DE SALUD
B2: =CONCATENATE("COMUNA: ",NOMBRE!B2," - ","( ",NOMBRE!C2,NOMBRE!D2,NOMBRE!E2,NOMBRE!F2,NOMBRE!G2," )") -> COMUNA: - ( )
B3: =CONCATENATE("ESTABLECIMIENTO/ESTRATEGIA: ",NOMBRE!B3," - ","( ",NOMBRE!C3,NOMBRE!D3,NOMBRE!E3,NOMBRE!F3,NOMBRE!G3,NOMBRE!H3," )") -> ESTABLECIMIENTO/ESTRATEGIA: - ( )
B4: =CONCATENATE("MES: ",NOMBRE!B6," - ","( ",NOMBRE!C6,NOMBRE!D6," )") -> MES: - ( )
B5: =CONCATENATE("AÑO: ",NOMBRE!B7) -> AÑO: 2020
B6: REM-A04. CONSULTAS Y OTRAS ATENCIONES EN LA RED
B8: SECCIÓN A: CONSULTAS MÉDICAS
A9: CODIGO DICCIONARIO | B9: TIPO DE CONSULTA | C9: TOTAL | F9: POR DE EDAD (en años) | AP9: Beneficiarios | AQ9: Pueblos Originarios | AR9: Migrantes | AS9: Niños, Niñas, Adolescentes y Jóvenes Población SENAME | AT9: Por Campaña de Invierno
F10: Menor de 1 | H10: 1 a 4 | J10: 5 a 9 | L10: 10 a 14 | N10: 15 a 19 | P10: 20 a 24 | R10: 25 - 29 | T10: 30 - 34 | V10: 35 - 39 | X10: 40 - 44 | Z10: 45 - 49 | AB10: 50 - 54 | AD10: 55 - 59 | AF10: 60 - 64 | AH10: 65 - 69 | AJ10: 70 - 74 | AL10: 75 - 79 | AN10: 80 y mas
C11: Ambos Sexos | D11: Hombres | E11: Mujeres | F11: Hombres | G11: Mujeres | H11: Hombres | I11: Mujeres | J11: Hombres | K11: Mujeres | L11: Hombres | M11: Mujeres | N11: Hombres | O11: Mujeres | P11: Hombres | Q11: Mujeres | R11: Hombres | S11: Mujeres | T11: Hombres | U11: Mujeres | V11: Hombres | W11: Mujeres | X11: Hombres | Y11: Mujeres | Z11: Hombres | AA11: Mujeres | AB11: Hombres | AC11: Mujeres | AD11: Hombres | AE11: Mujeres | AF11: Hombres | AG11: Mujeres | AH11: Hombres | AI11: Mujeres | AJ11: Hombres | AK11: Mujeres | AL11: Hombres | AM11: Mujeres | AN11: Hombres | AO11: Mujeres
B12: TOTAL | C12: =SUM(C13:C26) -> 0 | D12: =SUM(D13:D26) -> 0 | E12: =SUM(E13:E26) -> 0 | F12: =SUM(F13:F26) -> 0 | G12: =SUM(G13:G26) -> 0 | H12: =SUM(H13:H26) -> 0 | I12: =SUM(I13:I26) -> 0 | J12: =SUM(J13:J26) -> 0 | ... AT12: =SUM(AT13:AT26) -> 0
A13: 03020101 | B13: IRA ALTA | C13: COL01 | D13: COL02 | E13: COL03 | F13: COL04 | G13: COL05 | H13: COL06 | I13: COL07 | J13: COL08 | K13: COL09 | L13: COL10 | M13: COL11 | N13: COL12 | O13: COL13 | P13: COL14 | Q13: COL15 | R13: COL16 | S13: COL17 | T13: COL18 | U13: COL19 | V13: COL20 | W13: COL21 | X13: COL22 | Y13: COL23 | Z13: COL24 | AA13: COL25 | AB13: COL26 | AC13: COL27 | AD13: COL28 | AE13: COL29 | AF13: COL30 | AG13: COL31 | AH13: COL32 | AI13: COL33 | AJ13: COL34 | AK13: COL35 | AL13: COL36 | AM13: COL37 | AN13: COL38 | AO13: COL39 | AP13: COL40 | AQ13: COL41 | AR13: COL42 | AS13: COL43 | AT13: COL44 | CG13: 0 | CH13: 0 | CI13: 0 | CJ13: 0 | CK13: 0
A14: 03020201 | B14: SÍNDROME BRONQUIAL OBSTRUCTIVO | C14: COL01 | D14: COL02 | E14: COL03 | F14: COL04 | G14: COL05 | H14: COL06 | I14: COL07 | J14: COL08 | K14: COL09 | L14: COL10 | M14: COL11 | N14: COL12 | O14: COL13 | P14: COL14 | Q14: COL15 | R14: COL16 | S14: COL17 | T14: COL18 | U14: COL19 | V14: COL20 | W14: COL21 | X14: COL22 | Y14: COL23 | Z14: COL24 | AA14: COL25 | AB14: COL26 | AC14: COL27 | AD14: COL28 | AE14: COL29 | AF14: COL30 | AG14: COL31 | AH14: COL32 | AI14: COL33 | AJ14: COL34 | AK14: COL35 | AL14: COL36 | AM14: COL37 | AN14: COL38 | AO14: COL39 | AP14: COL40 | AQ14: COL41 | AR14: COL42 | AS14: COL43 | AT14: COL44 | CG14: 0 | CH14: 0 | CI14: 0 | CJ14: 0 | CK14: 0
A15: 03020301 | B15: NEUMONÍA | C15: COL01 | D15: COL02 | E15: COL03 | F15: COL04 | G15: COL05 | H15: COL06 | I15: COL07 | J15: COL08 | K15: COL09 | L15: COL10 | M15: COL11 | N15: COL12 | O15: COL13 | P15: COL14 | Q15: COL15 | R15: COL16 | S15: COL17 | T15: COL18 | U15: COL19 | V15: COL20 | W15: COL21 | X15: COL22 | Y15: COL23 | Z15: COL24 | AA15: COL25 | AB15: COL26 | AC15: COL27 | AD15: COL28 | AE15: COL29 | AF15: COL30 | AG15: COL31 | AH15: COL32 | AI15: COL33 | AJ15: COL34 | AK15: COL35 | AL15: COL36 | AM15: COL37 | AN15: COL38 | AO15: COL39 | AP15: COL40 | AQ15: COL41 | AR15: COL42 | AS15: COL43 | AT15: COL44 | CG15: 0 | CH15: 0 | CI15: 0 | CJ15: 0 | CK15: 0
A16: 03020402 | B16: ASMA | C16: COL01 | D16: COL02 | E16: COL03 | F16: COL04 | G16: COL05 | H16: COL06 | I16: COL07 | J16: COL08 | K16: COL09 | L16: COL10 | M16: COL11 | N16: COL12 | O16: COL13 | P16: COL14 | Q16: COL15 | R16: COL16 | S16: COL17 | T16: COL18 | U16: COL19 | V16: COL20 | W16: COL21 | X16: COL22 | Y16: COL23 | Z16: COL24 | AA16: COL25 | AB16: COL26 | AC16: COL27 | AD16: COL28 | AE16: COL29 | AF16: COL30 | AG16: COL31 | AH16: COL32 | AI16: COL33 | AJ16: COL34 | AK16: COL35 | AL16: COL36 | AM16: COL37 | AN16: COL38 | AO16: COL39 | AP16: COL40 | AQ16: COL41 | AR16: COL42 | AS16: COL43 | AT16: COL44 | CG16: 0 | CH16: 0 | CI16: 0 | CJ16: 0 | CK16: 0
A17: 03020403 | B17: ENFERMEDAD PULMONAR OBSTRUCTIVA CRÓNICA | C17: COL01 | D17: COL02 | E17: COL03 | F17: COL04 | G17: COL05 | H17: COL06 | I17: COL07 | J17: COL08 | K17: COL09 | L17: COL10 | M17: COL11 | N17: COL12 | O17: COL13 | P17: COL14 | Q17: COL15 | R17: COL16 | S17: COL17 | T17: COL18 | U17: COL19 | V17: COL20 | W17: COL21 | X17: COL22 | Y17: COL23 | Z17: COL24 | AA17: COL25 | AB17: COL26 | AC17: COL27 | AD17: COL28 | AE17: COL29 | AF17: COL30 | AG17: COL31 | AH17: COL32 | AI17: COL33 | AJ17: COL34 | AK17: COL35 | AL17: COL36 | AM17: COL37 | AN17: COL38 | AO17: COL39 | AP17: COL40 | AQ17: COL41 | AR17: COL42 | AS17: COL43 | AT17: COL44 | CG17: 0 | CH17: 0 | CI17: 0 | CJ17: 0 | CK17: 0
A18: 03020401 | B18: OTRAS RESPIRATORIAS | C18: COL01 | D18: COL02 | E18: COL03 | F18: COL04 | G18: COL05 | H18: COL06 | I18: COL07 | J18: COL08 | K18: COL09 | L18: COL10 | M18: COL11 | N18: COL12 | O18: COL13 | P18: COL14 | Q18: COL15 | R18: COL16 | S18: COL17 | T18: COL18 | U18: COL19 | V18: COL20 | W18: COL21 | X18: COL22 | Y18: COL23 | Z18: COL24 | AA18: COL25 | AB18: COL26 | AC18: COL27 | AD18: COL28 | AE18: COL29 | AF18: COL30 | AG18: COL31 | AH18: COL32 | AI18: COL33 | AJ18: COL34 | AK18: COL35 | AL18: COL36 | AM18: COL37 | AN18: COL38 | AO18: COL39 | AP18: COL40 | AQ18: COL41 | AR18: COL42 | AS18: COL43 | AT18: COL44 | CG18: 0 | CH18: 0 | CI18: 0 | CJ18: 0 | CK18: 0
A19: 03040210 | B19: OBSTETRICA | C19: COL01 | D19: COL02 | E19: COL03 | F19: COL04 | G19: COL05 | H19: COL06 | I19: COL07 | J19: COL08 | K19: COL09 | L19: COL10 | M19: COL11 | N19: COL12 | O19: COL13 | P19: COL14 | Q19: COL15 | R19: COL16 | S19: COL17 | T19: COL18 | U19: COL19 | V19: COL20 | W19: COL21 | X19: COL22 | Y19: COL23 | Z19: COL24 | AA19: COL25 | AB19: COL26 | AC19: COL27 | AD19: COL28 | AE19: COL29 | AF19: COL30 | AG19: COL31 | AH19: COL32 | AI19: COL33 | AJ19: COL34 | AK19: COL35 | AL19: COL36 | AM19: COL37 | AN19: COL38 | AO19: COL39 | AP19: COL40 | AQ19: COL41 | AR19: COL42 | AS19: COL43 | AT19: COL44 | CG19: 0 | CH19: 0 | CI19: 0 | CJ19: 0 | CK19: 0
A20: 03040220 | B20: GINECOLÓGICA | C20: COL01 | D20: COL02 | E20: COL03 | F20: COL04 | G20: COL05 | H20: COL06 | I20: COL07 | J20: COL08 | K20: COL09 | L20: COL10 | M20: COL11 | N20: COL12 | O20: COL13 | P20: COL14 | Q20: COL15 | R20: COL16 | S20: COL17 | T20: COL18 | U20: COL19 | V20: COL20 | W20: COL21 | X20: COL22 | Y20: COL23 | Z20: COL24 | AA20: COL25 | AB20: COL26 | AC20: COL27 | AD20: COL28 | AE20: COL29 | AF20: COL30 | AG20: COL31 | AH20: COL32 | AI20: COL33 | AJ20: COL34 | AK20: COL35 | AL20: COL36 | AM20: COL37 | AN20: COL38 | AO20: COL39 | AP20: COL40 | AQ20: COL41 | AR20: COL42 | AS20: COL43 | AT20: COL44 | CG20: 0 | CH20: 0 | CI20: 0 | CJ20: 0 | CK20: 0
A21: 04040100 | B21: GINECOLÓGICA POR INFERTILIDAD | C21: COL01 | D21: COL02 | E21: COL03 | F21: COL04 | G21: COL05 | H21: COL06 | I21: COL07 | J21: COL08 | K21: COL09 | L21: COL10 | M21: COL11 | N21: COL12 | O21: COL13 | P21: COL14 | Q21: COL15 | R21: COL16 | S21: COL17 | T21: COL18 | U21: COL19 | V21: COL20 | W21: COL21 | X21: COL22 | Y21: COL23 | Z21: COL24 | AA21: COL25 | AB21: COL26 | AC21: COL27 | AD21: COL28 | AE21: COL29 | AF21: COL30 | AG21: COL31 | AH21: COL32 | AI21: COL33 | AJ21: COL34 | AK21: COL35 | AL21: COL36 | AM21: COL37 | AN21: COL38 | AO21: COL39 | AP21: COL40 | AQ21: COL41 | AR21: COL42 | AS21: COL43 | AT21: COL44 | CG21: 0 | CH21: 0 | CI21: 0 | CJ21: 0 | CK21: 0
A22: 04025010 | B22: INFECCIÓN TRANSMISIÓN SEXUAL | C22: COL01 | D22: COL02 | E22: COL03 | F22: COL04 | G22: COL05 | H22: COL06 | I22: COL07 | J22: COL08 | K22: COL09 | L22: COL10 | M22: COL11 | N22: COL12 | O22: COL13 | P22: COL14 | Q22: COL15 | R22: COL16 | S22: COL17 | T22: COL18 | U22: COL19 | V22: COL20 | W22: COL21 | X22: COL22 | Y22: COL23 | Z22: COL24 | AA22: COL25 | AB22: COL26 | AC22: COL27 | AD22: COL28 | AE22: COL29 | AF22: COL30 | AG22: COL31 | AH22: COL32 | AI22: COL33 | AJ22: COL34 | AK22: COL35 | AL22: COL36 | AM22: COL37 | AN22: COL38 | AO22: COL39 | AP22: COL40 | AQ22: COL41 | AR22: COL42 | AS22: COL43 | AT22: COL44 | CG22: 0 | CH22: 0 | CI22: 0 | CJ22: 0 | CK22: 0
A23: 04025020 | B23: VIH-SIDA | C23: COL01 | D23: COL02 | E23: COL03 | F23: COL04 | G23: COL05 | H23: COL06 | I23: COL07 | J23: COL08 | K23: COL09 | L23: COL10 | M23: COL11 | N23: COL12 | O23: COL13 | P23: COL14 | Q23: COL15 | R23: COL16 | S23: COL17 | T23: COL18 | U23: COL19 | V23: COL20 | W23: COL21 | X23: COL22 | Y23: COL23 | Z23: COL24 | AA23: COL25 | AB23: COL26 | AC23: COL27 | AD23: COL28 | AE23: COL29 | AF23: COL30 | AG23: COL31 | AH23: COL32 | AI23: COL33 | AJ23: COL34 | AK23: COL35 | AL23: COL36 | AM23: COL37 | AN23: COL38 | AO23: COL39 | AP23: COL40 | AQ23: COL41 | AR23: COL42 | AS23: COL43 | AT23: COL44 | CG23: 0 | CH23: 0 | CI23: 0 | CJ23: 0 | CK23: 0
A24: 04025025 | B24: SALUD MENTAL | C24: COL01 | D24: COL02 | E24: COL03 | F24: COL04 | G24: COL05 | H24: COL06 | I24: COL07 | J24: COL08 | K24: COL09 | L24: COL10 | M24: COL11 | N24: COL12 | O24: COL13 | P24: COL14 | Q24: COL15 | R24: COL16 | S24: COL17 | T24: COL18 | U24: COL19 | V24: COL20 | W24: COL21 | X24: COL22 | Y24: COL23 | Z24: COL24 | AA24: COL25 | AB24: COL26 | AC24: COL27 | AD24: COL28 | AE24: COL29 | AF24: COL30 | AG24: COL31 | AH24: COL32 | AI24: COL33 | AJ24: COL34 | AK24: COL35 | AL24: COL36 | AM24: COL37 | AN24: COL38 | AO24: COL39 | AP24: COL40 | AQ24: COL41 | AR24: COL42 | AS24: COL43 | AT24: COL44 | CG24: 0 | CH24: 0 | CI24: 0 | CJ24: 0 | CK24: 0
... A26: 03020501 | B26: OTRAS MORBILIDADES | C26: COL01 | D26: COL02 | E26: COL03 | F26: COL04 | G26: COL05 | H26: COL06 | I26: COL07 | J26: COL08 | K26: COL09 | L26: COL10 | M26: COL11 | N26: COL12 | O26: COL13 | P26: COL14 | Q26: COL15 | R26: COL16 | S26: COL17 | T26: COL18 | U26: COL19 | V26: COL20 | W26: COL21 | X26: COL22 | Y26: COL23 | Z26: COL24 | AA26: COL25 | AB26: COL26 | AC26: COL27 | AD26: COL28 | AE26: COL29 | AF26: COL30 | AG26: COL31 | AH26: COL32 | AI26: COL33 | AJ26: COL34 | AK26: COL35 | AL26: COL36 | AM26: COL37 | AN26: COL38 | AO26: COL39 | AP26: COL40 | AQ26: COL41 | AR26: COL42 | AS26: COL43 | AT26: COL44 | CG26: 0 | CH26: 0 | CI26: 0 | CJ26: 0 | CK26: 0
B27: SECCIÓN B: CONSULTAS DE PROFESIONALES NO MÉDICOS
B28: PROFESIONAL | C28: TOTAL | F28: POR DE EDAD (en años) | AP28: Beneficiarios | AQ28: Pueblos Originarios | AR28: Migrantes | AS28: Espacios Amigables | AT28: Niños, Niñas, Adolescentes y Jóvenes Población SENAME
F29: Menor de 1 | H29: 1 a 4 | J29: 5 a 9 | L29: 10 a 14 | N29: 15 a 19 | P29: 20 a 24 | R29: 25 - 29 | T29: 30 - 34 | V29: 35 - 39 | X29: 40 - 44 | Z29: 45 - 49 | AB29: 50 - 54 | AD29: 55 - 59 | AF29: 60 - 64 | AH29: 65 - 69 | AJ29: 70 - 74 | AL29: 75 - 79 | AN29: 80 y mas
C30: Ambos Sexos | D30: Hombres | E30: Mujeres | F30: Hombres | G30: Mujeres | H30: Hombres | I30: Mujeres | J30: Hombres | K30: Mujeres | L30: Hombres | M30: Mujeres | N30: Hombres | O30: Mujeres | P30: Hombres | Q30: Mujeres | R30: Hombres | S30: Mujeres | T30: Hombres | U30: Mujeres | V30: Hombres | W30: Mujeres | X30: Hombres | Y30: Mujeres | Z30: Hombres | AA30: Mujeres | AB30: Hombres | AC30: Mujeres | AD30: Hombres | AE30: Mujeres | AF30: Hombres | AG30: Mujeres | AH30: Hombres | AI30: Mujeres | AJ30: Hombres | AK30: Mujeres | AL30: Hombres | AM30: Mujeres | AN30: Hombres | AO30: Mujeres
A31: 03020702 | B31: ENFERMERA /O | C31: COL01 | D31: COL02 | E31: COL03 | F31: COL04 | G31: COL05 | H31: COL06 | I31: COL07 | J31: COL08 | K31: COL09 | L31: COL10 | M31: COL11 | N31: COL12 | O31: COL13 | P31: COL14 | Q31: COL15 | R31: COL16 | S31: COL17 | T31: COL18 | U31: COL19 | V31: COL20 | W31: COL21 | X31: COL22 | Y31: COL23 | Z31: COL24 | AA31: COL25 | AB31: COL26 | AC31: COL27 | AD31: COL28 | AE31: COL29 | AF31: COL30 | AG31: COL31 | AH31: COL32 | AI31: COL33 | AJ31: COL34 | AK31: COL35 | AL31: COL36 | AM31: COL37 | AN31: COL38 | AO31: COL39 | AP31: COL40 | AQ31: COL41 | AR31: COL42 | AS31: COL43 | AT31: COL44 | CH31: 0 | CI31: 0
A32: 04025030 | B32: MATRONA /ÓN (MORB.GINECOLÓGICA) | C32: COL01 | D32: COL02 | E32: COL03 | F32: COL04 | G32: COL05 | H32: COL06 | I32: COL07 | J32: COL08 | K32: COL09 | L32: COL10 | M32: COL11 | N32: COL12 | O32: COL13 | P32: COL14 | Q32: COL15 | R32: COL16 | S32: COL17 | T32: COL18 | U32: COL19 | V32: COL20 | W32: COL21 | X32: COL22 | Y32: COL23 | Z32: COL24 | AA32: COL25 | AB32: COL26 | AC32: COL27 | AD32: COL28 | AE32: COL29 | AF32: COL30 | AG32: COL31 | AH32: COL32 | AI32: COL33 | AJ32: COL34 | AK32: COL35 | AL32: COL36 | AM32: COL37 | AN32: COL38 | AO32: COL39 | AP32: COL40 | AQ32: COL41 | AR32: COL42 | AS32: COL43 | AT32: COL44 | CH32: 0 | CI32: 0
A33: 04025040 | B33: MATRONA /ÓN (ITS) | C33: COL01 | D33: COL02 | E33: COL03 | F33: COL04 | G33: COL05 | H33: COL06 | I33: COL07 | J33: COL08 | K33: COL09 | L33: COL10 | M33: COL11 | N33: COL12 | O33: COL13 | P33: COL14 | Q33: COL15 | R33: COL16 | S33: COL17 | T33: COL18 | U33: COL19 | V33: COL20 | W33: COL21 | X33: COL22 | Y33: COL23 | Z33: COL24 | AA33: COL25 | AB33: COL26 | AC33: COL27 | AD33: COL28 | AE33: COL29 | AF33: COL30 | AG33: COL31 | AH33: COL32 | AI33: COL33 | AJ33: COL34 | AK33: COL35 | AL33: COL36 | AM33: COL37 | AN33: COL38 | AO33: COL39 | AP33: COL40 | AQ33: COL41 | AR33: COL42 | AS33: COL43 | AT33: COL44 | CH33: 0 | CI33: 0
A34: 04040200 | B34: MATRONA /ÓN (INFERTILIDAD) | C34: COL01 | D34: COL02 | E34: COL03 | F34: COL04 | G34: COL05 | H34: COL06 | I34: COL07 | J34: COL08 | K34: COL09 | L34: COL10 | M34: COL11 | N34: COL12 | O34: COL13 | P34: COL14 | Q34: COL15 | R34: COL16 | S34: COL17 | T34: COL18 | U34: COL19 | V34: COL20 | W34: COL21 | X34: COL22 | Y34: COL23 | Z34: COL24 | AA34: COL25 | AB34: COL26 | AC34: COL27 | AD34: COL28 | AE34: COL29 | AF34: COL30 | AG34: COL31 | AH34: COL32 | AI34: COL33 | AJ34: COL34 | AK34: COL35 | AL34: COL36 | AM34: COL37 | AN34: COL38 | AO34: COL39 | AP34: COL40 | AQ34: COL41 | AR34: COL42 | AS34: COL43 | AT34: COL44 | CH34: 0 | CI34: 0
A35: 04025050 | B35: MATRONA /ÓN (OTRAS CONSULTAS) | C35: COL01 | D35: COL02 | E35: COL03 | F35: COL04 | G35: COL05 | H35: COL06 | I35: COL07 | J35: COL08 | K35: COL09 | L35: COL10 | M35: COL11 | N35: COL12 | O35: COL13 | P35: COL14 | Q35: COL15 | R35: COL16 | S35: COL17 | T35: COL18 | U35: COL19 | V35: COL20 | W35: COL21 | X35: COL22 | Y35: COL23 | Z35: COL24 | AA35: COL25 | AB35: COL26 | AC35: COL27 | AD35: COL28 | AE35: COL29 | AF35: COL30 | AG35: COL31 | AH35: COL32 | AI35: COL33 | AJ35: COL34 | AK35: COL35 | AL35: COL36 | AM35: COL37 | AN35: COL38 | AO35: COL39 | AP35: COL40 | AQ35: COL41 | AR35: COL42 | AS35: COL43 | AT35: COL44 | CH35: 0 | CI35: 0
A36: 04050100 | B36: MATRONA /ÓN (SALUD SEXUAL) | C36: COL01 | D36: COL02 | E36: COL03 | F36: COL04 | G36: COL05 | H36: COL06 | I36: COL07 | J36: COL08 | K36: COL09 | L36: COL10 | M36: COL11 | N36: COL12 | O36: COL13 | P36: COL14 | Q36: COL15 | R36: COL16 | S36: COL17 | T36: COL18 | U36: COL19 | V36: COL20 | W36: COL21 | X36: COL22 | Y36: COL23 | Z36: COL24 | AA36: COL25 | AB36: COL26 | AC36: COL27 | AD36: COL28 | AE36: COL29 | AF36: COL30 | AG36: COL31 | AH36: COL32 | AI36: COL33 | AJ36: COL34 | AK36: COL35 | AL36: COL36 | AM36: COL37 | AN36: COL38 | AO36: COL39 | AP36: COL40 | AQ36: COL41 | AR36: COL42 | AS36: COL43 | AT36: COL44 | CH36: 0 | CI36: 0
A37: 03020604 | B37: NUTRICIONISTA (OTRAS CONSULTAS) | C37: COL01 | D37: COL02 | E37: COL03 | F37: COL04 | G37: COL05 | H37: COL06 | I37: COL07 | J37: COL08 | K37: COL09 | L37: COL10 | M37: COL11 | N37: COL12 | O37: COL13 | P37: COL14 | Q37: COL15 | R37: COL16 | S37: COL17 | T37: COL18 | U37: COL19 | V37: COL20 | W37: COL21 | X37: COL22 | Y37: COL23 | Z37: COL24 | AA37: COL25 | AB37: COL26 | AC37: COL27 | AD37: COL28 | AE37: COL29 | AF37: COL30 | AG37: COL31 | AH37: COL32 | AI37: COL33 | AJ37: COL34 | AK37: COL35 | AL37: COL36 | AM37: COL37 | AN37: COL38 | AO37: COL39 | AP37: COL40 | AQ37: COL41 | AR37: COL42 | AS37: COL43 | AT37: COL44 | CH37: 0 | CI37: 0
A38: 04050110 | B38: NUTRICIONISTA MAULNUTRICIÓN POR EXCESO | C38: COL01 | D38: COL02 | E38: COL03 | F38: COL04 | G38: COL05 | H38: COL06 | I38: COL07 | J38: COL08 | K38: COL09 | L38: COL10 | M38: COL11 | N38: COL12 | O38: COL13 | P38: COL14 | Q38: COL15 | R38: COL16 | S38: COL17 | T38: COL18 | U38: COL19 | V38: COL20 | W38: COL21 | X38: COL22 | Y38: COL23 | Z38: COL24 | AA38: COL25 | AB38: COL26 | AC38: COL27 | AD38: COL28 | AE38: COL29 | AF38: COL30 | AG38: COL31 | AH38: COL32 | AI38: COL33 | AJ38: COL34 | AK38: COL35 | AL38: COL36 | AM38: COL37 | AN38: COL38 | AO38: COL39 | AP38: COL40 | AQ38: COL41 | AR38: COL42 | AS38: COL43 | AT38: COL44 | CH38: 0 | CI38: 0
A39: 04050120 | B39: NUTRICIONISTA MALNUTRICIÓN POR DÉFICIT | C39: COL01 | D39: COL02 | E39: COL03 | F39: COL04 | G39: COL05 | H39: COL06 | I39: COL07 | J39: COL08 | K39: COL09 | L39: COL10 | M39: COL11 | N39: COL12 | O39: COL13 | P39: COL14 | Q39: COL15 | R39: COL16 | S39: COL17 | T39: COL18 | U39: COL19 | V39: COL20 | W39: COL21 | X39: COL22 | Y39: COL23 | Z39: COL24 | AA39: COL25 | AB39: COL26 | AC39: COL27 | AD39: COL28 | AE39: COL29 | AF39: COL30 | AG39: COL31 | AH39: COL32 | AI39: COL33 | AJ39: COL34 | AK39: COL35 | AL39: COL36 | AM39: COL37 | AN39: COL38 | AO39: COL39 | AP39: COL40 | AQ39: COL41 | AR39: COL42 | AS39: COL43 | AT39: COL44 | CH39: 0 | CI39: 0
A40: 03020908 | B40: PSICÓLOGO/A | C40: COL01 | D40: COL02 | E40: COL03 | F40: COL04 | G40: COL05 | H40: COL06 | I40: COL07 | J40: COL08 | K40: COL09 | L40: COL10 | M40: COL11 | N40: COL12 | O40: COL13 | P40: COL14 | Q40: COL15 | R40: COL16 | S40: COL17 | T40: COL18 | U40: COL19 | V40: COL20 | W40: COL21 | X40: COL22 | Y40: COL23 | Z40: COL24 | AA40: COL25 | AB40: COL26 | AC40: COL27 | AD40: COL28 | AE40: COL29 | AF40: COL30 | AG40: COL31 | AH40: COL32 | AI40: COL33 | AJ40: COL34 | AK40: COL35 | AL40: COL36 | AM40: COL37 | AN40: COL38 | AO40: COL39 | AP40: COL40 | AQ40: COL41 | AR40: COL42 | AS40: COL43 | AT40: COL44 | CH40: 0 | CI40: 0
A41: 03030250 | B41: FONOAUDIÓLOGO | C41: COL01 | D41: COL02 | E41: COL03 | F41: COL04 | G41: COL05 | H41: COL06 | I41: COL07 | J41: COL08 | K41: COL09 | L41: COL10 | M41: COL11 | N41: COL12 | O41: COL13 | P41: COL14 | Q41: COL15 | R41: COL16 | S41: COL17 | T41: COL18 | U41: COL19 | V41: COL20 | W41: COL21 | X41: COL22 | Y41: COL23 | Z41: COL24 | AA41: COL25 | AB41: COL26 | AC41: COL27 | AD41: COL28 | AE41: COL29 | AF41: COL30 | AG41: COL31 | AH41: COL32 | AI41: COL33 | AJ41: COL34 | AK41: COL35 | AL41: COL36 | AM41: COL37 | AN41: COL38 | AO41: COL39 | AP41: COL40 | AQ41: COL41 | AR41: COL42 | AS41: COL43 | AT41: COL44 | CH41: 0 | CI41: 0
A42: 03030270 | B42: TERAPEUTA OCUPACIONAL | C42: COL01 | D42: COL02 | E42: COL03 | F42: COL04 | G42: COL05 | H42: COL06 | I42: COL07 | J42: COL08 | K42: COL09 | L42: COL10 | M42: COL11 | N42: COL12 | O42: COL13 | P42: COL14 | Q42: COL15 | R42: COL16 | S42: COL17 | T42: COL18 | U42: COL19 | V42: COL20 | W42: COL21 | X42: COL22 | Y42: COL23 | Z42: COL24 | AA42: COL25 | AB42: COL26 | AC42: COL27 | AD42: COL28 | AE42: COL29 | AF42: COL30 | AG42: COL31 | AH42: COL32 | AI42: COL33 | AJ42: COL34 | AK42: COL35 | AL42: COL36 | AM42: COL37 | AN42: COL38 | AO42: COL39 | AP42: COL40 | AQ42: COL41 | AR42: COL42 | AS42: COL43 | AT42: COL44 | CH42: 0 | CI42: 0
...

Sheet A05
B1: SERVICIO DE SALUD
B2: =CONCATENATE("COMUNA: ",NOMBRE!B2," - ","( ",NOMBRE!C2,NOMBRE!D2,NOMBRE!E2,NOMBRE!F2,NOMBRE!G2," )") -> COMUNA: - ( )
B3: =CONCATENATE("ESTABLECIMIENTO/ESTRATEGIA: ",NOMBRE!B3," - ","( ",NOMBRE!C3,NOMBRE!D3,NOMBRE!E3,NOMBRE!F3,NOMBRE!G3,NOMBRE!H3," )") -> ESTABLECIMIENTO/ESTRATEGIA: - ( )
B4: =CONCATENATE("MES: ",NOMBRE!B6," - ","( ",NOMBRE!C6,NOMBRE!D6," )") -> MES: - ( )
B5: =CONCATENATE("AÑO: ",NOMBRE!B7) -> AÑO: 2020
B6: REM-A05. INGRESOS Y EGRESOS POR CONDICIÓN Y PROBLEMAS DE SALUD
B8: SECCIÓN A: INGRESOS DE GESTANTES A PROGRAMA PRENATAL
A9: CODIGO DICCIONARIO | B9: CONDICIÓN | D9: TOTAL | E9: POR DE EDAD (en años) | O9: Victima de violencia de genero | P9: Pueblos Originarios | Q9: Migrantes
E10: Menor de 15 | F10: 15 - 19 | G10: 20 - 24 | H10: 25 - 29 | I10: 30 - 34 | J10: 35 - 39 | K10: 40 - 44 | L10: 45 - 49 | M10: 50 - 54 | N10: 55 y más
A11: 01080008 | B11: GESTANTES INGRESADAS | D11: COL01 | E11: COL02 | F11: COL03 | G11: COL04 | H11: COL05 | I11: COL06 | J11: COL07 | K11: COL08 | L11: COL09 | M11: COL10 | N11: COL11 | O11: COL12 | P11: COL13 | Q11: COL14 | R11: =CB11&CC11&CD11&CE11 -> * El número de víctima de Violencia de Género NO DEBE ser diferente al Total. * Pueblo Originario y/o Migrantes NO DEBEN ser Mayor al Total. | CB11: =IF(CI11=1,"* El número de víctima de Violencia de Género NO DEBE ser diferente al Total. ","") -> * El número de víctima de Violencia de Género NO DEBE ser diferente al Total. | CC11: =IF(AND(D11<>0,OR(P11="",Q11="")),"* No olvide digitar los campos Pueblo Originario y/o Migrantes (Digite CEROS si no tiene). ","") | CD11: =IF(CK11=1,"* Pueblo Originario y/o Migrantes NO DEBEN ser Mayor al Total. ","") -> * Pueblo Originario y/o Migrantes NO DEBEN ser Mayor al Total. | CE11: =IF(CL11=1,"* Total Gestantes Ingresadas a control prenatal debe ser Mayor o Igual que el Total de Evaluaciones a Gestantes de REM A03 Sección B2. ","") | CI11: =IF(D11<O11,1,0) -> 1 | CK11: =IF(OR(D11<P11,D11<Q11),1,0) -> 1 | CL11: =IF(D11<'A03'!D75,1,0) -> 0
A12: 01080010 | B12: PRIMIGESTAS INGRESADAS | D12: COL01 | E12: COL02 | F12: COL03 | G12: COL04 | H12: COL05 | I12: COL06 | J12: COL07 | K12: COL08 | L12: COL09 | M12: COL10 | N12: COL11 | O12: COL12 | P12: COL13 | Q12: COL14 | R12: =CB12&CC12&CD12&CE12 -> * El número de víctima de Violencia de Género NO DEBE ser diferente al Total. * Pueblo Originario y/o Migrantes NO DEBEN ser Mayor al Total. | CB12: =IF(CI12=1,"* El número de víctima de Violencia de Género NO DEBE ser diferente al Total. ","") -> * El número de víctima de Violencia de Género NO DEBE ser diferente al Total. | CC12: =IF(AND(D12<>0,OR(P12="",Q12="")),"* No olvide digitar los campos Pueblo Originario y/o Migrantes (Digite CEROS si no tiene). ","") | CD12: =IF(CK12=1,"* Pueblo Originario y/o Migrantes NO DEBEN ser Mayor al Total. ","") -> * Pueblo Originario y/o Migrantes NO DEBEN ser Mayor al Total. | CE12: =IF(CL12=1,"* Total Gestantes debe ser Mayor o Igual a "&B12&".","") | CI12: =IF(D12<O12,1,0) -> 1 | CK12: =IF(OR(D12<P12,D12<Q12),1,0) -> 1 | CL12: =IF($D$11<D12,1,0) -> 0
A13: 01080009 | B13: GESTANTES INGRESADAS ANTES DE LAS 14 SEMANAS | D13: COL01 | E13: COL02 | F13: COL03 | G13: COL04 | H13: COL05 | I13: COL06 | J13: COL07 | K13: COL08 | L13: COL09 | M13: COL10 | N13: COL11 | O13: COL12 | P13: COL13 | Q13: COL14 | R13: =CB13&CC13&CD13&CE13 -> * El número de víctima de Violencia de Género NO DEBE ser diferente al Total. * Pueblo Originario y/o Migrantes NO DEBEN ser Mayor al Total. | CB13: =IF(CI13=1,"* El número de víctima de Violencia de Género NO DEBE ser diferente al Total. ","") -> * El número de víctima de Violencia de Género NO DEBE ser diferente al Total. | CC13: =IF(AND(D13<>0,OR(P13="",Q13="")),"* No olvide digitar los campos Pueblo Originario y/o Migrantes (Digite CEROS si no tiene). ","") | CD13: =IF(CK13=1,"* Pueblo Originario y/o Migrantes NO DEBEN ser Mayor al Total. ","") -> * Pueblo Originario y/o Migrantes NO DEBEN ser Mayor al Total. | CE13: =IF(CL13=1,"* Total Gestantes debe ser Mayor o Igual a "&B13&".","") | CI13: =IF(D13<O13,1,0) -> 1 | CK13: =IF(OR(D13<P13,D13<Q13),1,0) -> 1 | CL13: =IF($D$11<D13,1,0) -> 0
