Workbook

Sheet 2010
B2: Prevalencia de Consumo Ultimo Año | I2: N° de Personas con Consumo Ultimo Año
B3: SEXO | D3: GRUPO DE EDAD | F3: Total | I3: SEXO | K3: GRUPO DE EDAD | M3: Total
B4: Hombre | C4: Mujer | D4: 12-17 años | E4: 18-64 años | I4: Hombre | J4: Mujer | K4: 12-17 años | L4: 18-64 años
A5: Drogas(1) | B5: =B51 -> 7.492392 | C5: =C51 -> 2.180396 | D5: =D51 -> 5.609346 | E5: =E51 -> 4.62126 | F5: =F51 -> 4.808808 | H5: Drogas(1) | I5: =G51 -> 353549.2 | J5: =H51 -> 105047.7 | K5: =I51 -> 101536.7 | L5: =J51 -> 357060.1 | M5: =K51 -> 458596.8
A6: Alcohol | B6: =B52 -> 63.73841 | C6: =C52 -> 51.41955 | D6: =D52 -> 35.66034 | E6: =E52 -> 62.63505 | F6: =F52 -> 57.515 | H6: Alcohol | I6: =G52 -> 3007672 | J6: =H52 -> 2477305 | K6: =I52 -> 645500.1 | L6: =J52 -> 4839477 | M6: =K52 -> 5484977
A7: Sustancias(2) | B7: =B53 -> 63.9484 | C7: =C53 -> 51.50422 | D7: =D53 -> 35.88668 | E7: =E53 -> 62.76307 | F7: =F53 -> 57.66168 | H7: Sustancias(2) | I7: =G53 -> 3017581 | J7: =H53 -> 2481384 | K7: =I53 -> 649597.1 | L7: =J53 -> 4849368 | M7: =K53 -> 5498965
A8: (1) Prevalentes de último año de marihuana, cocaína y/o pasta base | H8: (1) Prevalentes de último año de marihuana, cocaína y/o pasta base
A9: (2) Prevalentes de último año de drogas y/o alcohol | H9: (2) Prevalentes de último año de drogas y/o alcohol
A10: Fuente: Elaboración Propia, Décimo Primer Estudio Nacional de Drogas en Población General, SENDA | H10: Fuente: Elaboración Propia, Décimo Primer Estudio Nacional de Drogas en Población General, SENDA
B12: Prevalencia de Consumo Problemático Ultimo Año | I12: N° de Personas con Consumo Problemático Ultimo Año
B13: SEXO | D13: GRUPO DE EDAD | F13: Total | I13: SEXO | K13: GRUPO DE EDAD | M13: Total
B14: Hombre | C14: Mujer | D14: 12-17 años | E14: 18-64 años | I14: Hombre | J14: Mujer | K14: 12-17 años | L14: 18-64 años
A15: Drogas(1) | B15: =B54 -> 29.18813 | C15: =C54 -> 20.20155 | D15: =D54 -> 36.5121 | E15: =E54 -> 24.46155 | F15: =F54 -> 27.12963 | H15: Drogas(1) | I15: =G54 -> 103194.4 | J15: =H54 -> 21221.26 | K15: =I54 -> 37073.19 | L15: =J54 -> 87342.45 | M15: =K54 -> 124415.6
A16: Alcohol(2) | B16: =B55 -> 11.89491 | C16: =C55 -> 5.672626 | D16: =D55 -> 11.91314 | E16: =E55 -> 8.707322 | F16: =F55 -> 9.084599 | H16: Alcohol(2) | I16: =G55 -> 357759.9 | J16: =H55 -> 140528.2 | K16: =I55 -> 76899.3 | L16: =J55 -> 421388.8 | M16: =K55 -> 498288.1
A17: Sustancias | B17: =B56 -> 13.30911 | C17: =C56 -> 6.099364 | D17: =D56 -> 15.00183 | E17: =E56 -> 9.393192 | F17: =F56 -> 10.05575 | H17: Sustancias | I17: =G56 -> 401613.3 | J17: =H56 -> 151348.6 | K17: =I56 -> 97451.48 | L17: =J56 -> 455510.4 | M17: =K56 -> 552961.9
A18: (1) Presencia de síntomas de dependencia (CIE-10) y/o abuso (DSM IV) sobre quienes declaran consumo de último año de marihuana, cocaína y/o pasta base | H18: (1) Presencia de síntomas de dependencia (CIE-10) y/o abuso (DSM IV) sobre quienes declaran consumo de último año de marihuana, cocaína y/o pasta base
A19: (2) Presencia de a lo menos un síntoma de abuso (DSM IV) sobre quienes declaran consumo de último año de alcohol | H19: (2) Presencia de a lo menos un síntoma de abuso (DSM IV) sobre quienes declaran consumo de último año de alcohol
A20: Fuente: Elaboración Propia, Décimo Primer Estudio Nacional de Drogas en Población General, SENDA | H20: Fuente: Elaboración Propia, Décimo Primer Estudio Nacional de Drogas en Población General, SENDA
B22: Prevalencia Tratamiento el último año (de los problemáticos)(1) | I22: N° de Personas Tratadas el último año (de los problemáticos)(1)
B23: SEXO | D23: GRUPO DE EDAD | F23: Total | I23: SEXO | K23: GRUPO DE EDAD | M23: Total
B24: Hombre | C24: Mujer | D24: 12-17 años | E24: 18-64 años | I24: Hombre | J24: Mujer | K24: 12-17 años | L24: 18-64 años
A25: Drogas | B25: =B57 -> 8.531023 | C25: =C57 -> 2.515957 | D25: =D57 -> 7.685071 | E25: =E57 -> 7.428636 | F25: =F57 -> 7.505048 | H25: Drogas | I25: =G57 -> 8803.535 | J25: =H57 -> 533.9178 | K25: =I57 -> 2849.101 | L25: =J57 -> 6488.353 | M25: =K57 -> 9337.453
A26: Alcohol | B26: =B58 -> 5.312783 | C26: =C58 -> 3.578035 | D26: =D58 -> 3.704977 | E26: =E58 -> 5.027674 | F26: =F58 -> 4.823546 | H26: Alcohol | I26: =G58 -> 19007.01 | J26: =H58 -> 5028.15 | K26: =I58 -> 2849.101 | L26: =J58 -> 21186.05 | M26: =K58 -> 24035.16
A27: Sustancias | B27: =B59 -> 5.447048 | C27: =C59 -> 3.322231 | D27: =D59 -> 2.923609 | E27: =E59 -> 5.280915 | F27: =F59 -> 4.865474 | H27: Sustancias | I27: =G59 -> 21876.07 | J27: =H59 -> 5028.15 | K27: =I59 -> 2849.101 | L27: =J59 -> 24055.12 | M27: =K59 -> 26904.22
A28: (1) Calculado a partir de aquellos individuos que presenten consumo problemático en el último año | H28: (1) Calculado a partir de aquellos individuos que presenten consumo problemático en el último año
A29: Fuente: Elaboración Propia, Décimo Primer Estudio Nacional de Drogas en Población General, SENDA | H29: Fuente: Elaboración Propia, Décimo Primer Estudio Nacional de Drogas en Población General, SENDA
B31: Prevalencia Personas que desearon Tratarse (de los problemáticos no tratados)(1) | I31: N° de Personas que desearon Tratarse (de los problemáticos no tratados)(1)
B32: SEXO | D32: GRUPO DE EDAD | F32: Total | I32: SEXO | K32: GRUPO DE EDAD | M32: Total
B33: Hombre | C33: Mujer | D33: 12-17 años | E33: 18-64 años | I33: Hombre | J33: Mujer | K33: 12-17 años | L33: 18-64 años
A34: Drogas | B34: =B60 -> 26.22032 | C34: =C60 -> 7.754001 | D34: =D60 -> 10.39328 | E34: =E60 -> 28.19482 | F34: =F60 -> 22.90067 | H34: Drogas | I34: =G60 -> 24749.58 | J34: =H60 -> 1604.097 | K34: =I60 -> 3557.007 | L34: =J60 -> 22796.67 | M34: =K60 -> 26353.67
A35: Alcohol | B35: =B61 -> 9.054935 | C35: =C61 -> 2.231606 | D35: =D61 -> 3.448236 | E35: =E61 -> 7.782118 | F35: =F61 -> 7.105423 | H35: Alcohol | I35: =G61 -> 30673.85 | J35: =H61 -> 3023.829 | K35: =I61 -> 2553.426 | L35: =J61 -> 31144.25 | M35: =K61 -> 33697.68
A36: Sustancias | B36: =B62 -> 10.48066 | C36: =C62 -> 2.066579 | D36: =D62 -> 4.568436 | E36: =E62 -> 8.923509 | F36: =F62 -> 8.140325 | H36: Sustancias | I36: =G62 -> 39798.97 | J36: =H62 -> 3023.829 | K36: =I62 -> 4321.85 | L36: =J62 -> 38500.95 | M36: =K62 -> 42822.8
A37: (1) Calculado a partir de aquellos individuos que presenten consumo problemático y declaren no haber sido tratados por alcohol y/o drogas | H37: (1) Calculado a partir de aquellos individuos que presenten consumo problemático y declaren no haber sido tratados por alcohol y/o drogas
A38: Fuente: Elaboración Propia, Décimo Primer Estudio Nacional de Drogas en Población General, SENDA | H38: Fuente: Elaboración Propia, Décimo Primer Estudio Nacional de Drogas en Población General, SENDA
B40: Prevalencia Personas que intentaron Tratarse (de los problemáticos no tratados y que deseaban tratarse)(1) | I40: N° de Personas que intentaronTratarse (de los problemáticos no tratados y que deseaban tratarse)(1)
B41: SEXO | D41: GRUPO DE EDAD | F41: Total | I41: SEXO | K41: GRUPO DE EDAD | M41: Total
B42: Hombre | C42: Mujer | D42: 12-17 años | E42: 18-64 años | I42: Hombre | J42: Mujer | K42: 12-17 años | L42: 18-64 años
A43: Drogas | B43: =B63 -> 34.05842 | C43: =C63 -> 100 | D43: =D63 -> 24.70698 | E43: =E63 -> 40.15755 | F43: =F63 -> 38.07215 | H43: Drogas | I43: =G63 -> 8429.313 | J43: =H63 -> 1604.097 | K43: =I63 -> 878.8291 | L43: =J63 -> 9154.582 | M43: =K63 -> 10033.41
A44: Alcohol | B44: =B64 -> 32.83433 | C44: =C64 -> 63.51007 | D44: =D64 -> 34.41764 | E44: =E64 -> 35.68286 | F44: =F64 -> 35.58699 | H44: Alcohol | I44: =G64 -> 10071.55 | J44: =H64 -> 1920.436 | K44: =I64 -> 878.8291 | L44: =J64 -> 11113.16 | M44: =K64 -> 11991.99
A45: Sustancias | B45: =B65 -> 36.76991 | C45: =C65 -> 63.51007 | D45: =D65 -> 20.33456 | E45: =E65 -> 40.71498 | F45: =F65 -> 38.6581 | H45: Sustancias | I45: =G65 -> 14634.05 | J45: =H65 -> 1920.436 | K45: =I65 -> 878.8291 | L45: =J65 -> 15675.65 | M45: =K65 -> 16554.48
...

Sheet 2012
B2: Prevalencia de Consumo Ultimo Año | I2: N° de Personas con Consumo Ultimo Año
B3: SEXO | D3: GRUPO DE EDAD | F3: Total | I3: SEXO | K3: GRUPO DE EDAD | M3: Total
B4: Hombre | C4: Mujer | D4: 12-17 años | E4: 18-64 años | I4: Hombre | J4: Mujer | K4: 12-17 años | L4: 18-64 años
A5: Drogas(1) | B5: =B51 -> 10.22489 | C5: =C51 -> 4.546884 | D5: =D51 -> 7.877769 | E5: =E51 -> 7.218318 | F5: =F51 -> 7.347374 | H5: Drogas(1) | I5: =G51 -> 490780.3 | J5: =H51 -> 224246.4 | K5: =I51 -> 150034.4 | L5: =J51 -> 564992.3 | M5: =K51 -> 715026.8
A6: Alcohol | B6: =B52 -> 61.75066 | C6: =C52 -> 49.96091 | D6: =D52 -> 35.30473 | E6: =E52 -> 60.75689 | F6: =F52 -> 55.77582 | H6: Alcohol | I6: =G52 -> 2963946 | J6: =H52 -> 2464007 | K6: =I52 -> 672389 | L6: =J52 -> 4755564 | M6: =K52 -> 5427953
A7: Sustancias(2) | B7: =B53 -> 62.47563 | C7: =C53 -> 50.32739 | D7: =D53 -> 36.03506 | E7: =E53 -> 61.25467 | F7: =F53 -> 56.31912 | H7: Sustancias(2) | I7: =G53 -> 2998743 | J7: =H53 -> 2482082 | K7: =I53 -> 686298.4 | L7: =J53 -> 4794527 | M7: =K53 -> 5480825
A8: (1) Prevalentes de último año de marihuana, cocaína y/o pasta base | H8: (1) Prevalentes de último año de marihuana, cocaína y/o pasta base
A9: (2) Prevalentes de último año de drogas y/o alcohol | H9: (2) Prevalentes de último año de drogas y/o alcohol
A10: Fuente: Elaboración Propia, Décimo Primer Estudio Nacional de Drogas en Población General, SENDA | H10: Fuente: Elaboración Propia, Décimo Primer Estudio Nacional de Drogas en Población General, SENDA
B12: Prevalencia de Consumo Problemático Ultimo Año | I12: N° de Personas con Consumo Problemático Ultimo Año
B13: SEXO | D13: GRUPO DE EDAD | F13: Total | I13: SEXO | K13: GRUPO DE EDAD | M13: Total
B14: Hombre | C14: Mujer | D14: 12-17 años | E14: 18-64 años | I14: Hombre | J14: Mujer | K14: 12-17 años | L14: 18-64 años
A15: Drogas(1) | B15: =B54 -> 29.63301 | C15: =C54 -> 24.88041 | D15: =D54 -> 32.08568 | E15: =E54 -> 27.09538 | F15: =F54 -> 28.1425 | H15: Drogas(1) | I15: =G54 -> 145433 | J15: =H54 -> 55793.43 | K15: =I54 -> 48139.57 | L15: =J54 -> 153086.8 | M15: =K54 -> 201226.4
A16: Alcohol(2) | B16: =B55 -> 11.50493 | C16: =C55 -> 3.284484 | D16: =D55 -> 9.129792 | E16: =E55 -> 7.581481 | F16: =F55 -> 7.773279 | H16: Alcohol(2) | I16: =G55 -> 341000 | J16: =H55 -> 80929.93 | K16: =I55 -> 61387.72 | L16: =J55 -> 360542.2 | M16: =K55 -> 421929.9
A17: Sustancias | B17: =B56 -> 13.4932 | C17: =C56 -> 4.619205 | D17: =D56 -> 12.10898 | E17: =E56 -> 9.097356 | F17: =F56 -> 9.474465 | H17: Sustancias | I17: =G56 -> 404626.4 | J17: =H56 -> 114652.5 | K17: =I56 -> 83103.73 | L17: =J56 -> 436175.2 | M17: =K56 -> 519278.9
A18: (1) Presencia de síntomas de dependencia (CIE-10) y/o abuso (DSM IV) sobre quienes declaran consumo de último año de marihuana, cocaína y/o pasta base | H18: (1) Presencia de síntomas de dependencia (CIE-10) y/o abuso (DSM IV) sobre quienes declaran consumo de último año de marihuana, cocaína y/o pasta base
A19: (2) Presencia de a lo menos un síntoma de abuso (DSM IV) sobre quienes declaran consumo de último año de alcohol | H19: (2) Presencia de a lo menos un síntoma de abuso (DSM IV) sobre quienes declaran consumo de último año de alcohol
A20: Fuente: Elaboración Propia, Décimo Primer Estudio Nacional de Drogas en Población General, SENDA | H20: Fuente: Elaboración Propia, Décimo Primer Estudio Nacional de Drogas en Población General, SENDA
B22: Prevalencia Tratamiento el último año (de los problemáticos)(1) | I22: N° de Personas Tratadas el último año (de los problemáticos)(1)
B23: SEXO | D23: GRUPO DE EDAD | F23: Total | I23: SEXO | K23: GRUPO DE EDAD | M23: Total
B24: Hombre | C24: Mujer | D24: 12-17 años | E24: 18-64 años | I24: Hombre | J24: Mujer | K24: 12-17 años | L24: 18-64 años
A25: Drogas | B25: =B57 -> 5.779784 | C25: =C57 -> 0.5751311 | D25: =D57 -> 2.886544 | E25: =E57 -> 4.792722 | F25: =F57 -> 4.336706 | H25: Drogas | I25: =G57 -> 8405.711 | J25: =H57 -> 320.8854 | K25: =I57 -> 1389.57 | L25: =J57 -> 7337.026 | M25: =K57 -> 8726.597
A26: Alcohol | B26: =B58 -> 5.931454 | C26: =C58 -> 8.312697 | D26: =D58 -> 5.041494 | E26: =E58 -> 6.617495 | F26: =F58 -> 6.388198 | H26: Alcohol | I26: =G58 -> 20226.26 | J26: =H58 -> 6727.46 | K26: =I58 -> 3094.858 | L26: =J58 -> 23858.86 | M26: =K58 -> 26953.72
A27: Sustancias | B27: =B59 -> 6.256352 | C27: =C59 -> 6.147575 | D27: =D59 -> 4.402245 | E27: =E59 -> 6.581019 | F27: =F59 -> 6.232335 | H27: Sustancias | I27: =G59 -> 25314.85 | J27: =H59 -> 7048.346 | K27: =I59 -> 3658.43 | L27: =J59 -> 28704.77 | M27: =K59 -> 32363.2
A28: (1) Calculado a partir de aquellos individuos que presenten consumo problemático en el último año | H28: (1) Calculado a partir de aquellos individuos que presenten consumo problemático en el último año
A29: Fuente: Elaboración Propia, Décimo Primer Estudio Nacional de Drogas en Población General, SENDA | H29: Fuente: Elaboración Propia, Décimo Primer Estudio Nacional de Drogas en Población General, SENDA
B31: Prevalencia Personas que desearon Tratarse (de los problemáticos no tratados)(1) | I31: N° de Personas que desearon Tratarse (de los problemáticos no tratados)(1)
B32: SEXO | D32: GRUPO DE EDAD | F32: Total | I32: SEXO | K32: GRUPO DE EDAD | M32: Total
B33: Hombre | C33: Mujer | D33: 12-17 años | E33: 18-64 años | I33: Hombre | J33: Mujer | K33: 12-17 años | L33: 18-64 años
A34: Drogas | B34: =B60 -> 1.118437 | C34: =C60 -> 1.443398 | D34: =D60 -> 1.025237 | E34: =E60 -> 1.272012 | F34: =F60 -> 1.212081 | H34: Drogas
A35: Alcohol | B35: =B61 -> 4.006068 | C35: =C61 -> 0.6459329 | D35: =D61 -> 0.8222244 | E35: =E61 -> 3.816766 | F35: =F61 -> 3.374814 | H35: Alcohol
A36: Sustancias | B36: =B62 -> 3.578274 | C36: =C62 -> 0.744107 | D36: =D62 -> 0.6033058 | E36: =E62 -> 3.409867 | F36: =F62 -> 2.951948 | H36: Sustancias
A37: (1) Calculado a partir de aquellos individuos que presenten consumo problemático y declaren no haber sido tratados por alcohol y/o drogas | H37: (1) Calculado a partir de aquellos individuos que presenten consumo problemático y declaren no haber sido tratados por alcohol y/o drogas
A38: Fuente: Elaboración Propia, Décimo Primer Estudio Nacional de Drogas en Población General, SENDA | H38: Fuente: Elaboración Propia, Décimo Primer Estudio Nacional de Drogas en Población General, SENDA
B40: Prevalencia Personas que intentaron Tratarse (de los problemáticos no tratados y que deseaban tratarse)(1) | I40: N° de Personas que intentaronTratarse (de los problemáticos no tratados y que deseaban tratarse)(1)
B41: SEXO | D41: GRUPO DE EDAD | F41: Total | I41: SEXO | K41: GRUPO DE EDAD | M41: Total
B42: Hombre | C42: Mujer | D42: 12-17 años | E42: 18-64 años | I42: Hombre | J42: Mujer | K42: 12-17 años | L42: 18-64 años
A43: Drogas | B43: =B63 -> 1.118437 | C43: =C63 -> 1.443398 | D43: =D63 -> 1.025237 | E43: =E63 -> 1.272012 | F43: =F63 -> 1.212081 | H43: Drogas | I43: =G63 -> 1532.564 | J43: =H63 -> 800.6897 | K43: =I63 -> 479.2981 | L43: =J63 -> 1853.955 | M43: =K63 -> 2333.254
A44: Alcohol | B44: =B64 -> 4.006068 | C44: =C64 -> 0.6459329 | D44: =D64 -> 0.8222244 | E44: =E64 -> 3.816766 | F44: =F64 -> 3.374814 | H44: Alcohol | I44: =G64 -> 12850.41 | J44: =H64 -> 479.2981 | K44: =I64 -> 479.2981 | L44: =J64 -> 12850.41 | M44: =K64 -> 13329.71
A45: Sustancias | B45: =B65 -> 3.578274 | C45: =C65 -> 0.744107 | D45: =D65 -> 0.6033058 | E45: =E65 -> 3.409867 | F45: =F65 -> 2.951948 | H45: Sustancias | I45: =G65 -> 13572.81 | J45: =H65 -> 800.6897 | K45: =I65 -> 479.2981 | L45: =J65 -> 13894.2 | M45: =K65 -> 14373.5
...

Sheet 2014
B2: Prevalencia de Consumo Ultimo Año | I2: N° de Personas con Consumo Ultimo Año
B3: SEXO | D3: GRUPO DE EDAD | F3: Total | I3: SEXO | K3: GRUPO DE EDAD | M3: Total
B4: Hombre | C4: Mujer | D4: 12-17 años | E4: 18-64 años | I4: Hombre | J4: Mujer | K4: 12-17 años | L4: 18-64 años
A5: Drogas(1) | B5: =B51 -> 15.16685 | C5: =C51 -> 8.235289 | D5: =D51 -> 9.611295 | E5: =E51 -> 11.90411 | F5: =F51 -> 11.6637 | H5: Drogas(1) | I5: =G51 -> 737276.2 | J5: =H51 -> 409053.3 | K5: =I51 -> 99047.2 | L5: =J51 -> 1047282 | M5: =K51 -> 1146330
A6: Alcohol | B6: =B52 -> 68.94965 | C6: =C52 -> 58.00744 | D6: =D52 -> 30.78188 | E6: =E52 -> 67.24262 | F6: =F52 -> 63.41955 | H6: Alcohol | I6: =G52 -> 3351713 | J6: =H52 -> 2881276 | K6: =I52 -> 317216.3 | L6: =J52 -> 5915773 | M6: =K52 -> 6232989
A7: Sustancias(2) | B7: =B53 -> 70.06578 | C7: =C53 -> 58.57576 | D7: =D53 -> 31.88034 | E7: =E53 -> 68.05154 | F7: =F53 -> 64.25882 | H7: Sustancias(2) | I7: =G53 -> 3405969 | J7: =H53 -> 2909505 | K7: =I53 -> 328536.3 | L7: =J53 -> 5986938 | M7: =K53 -> 6315474
A8: (1) Prevalentes de último año de marihuana, cocaína y/o pasta base | H8: (1) Prevalentes de último año de marihuana, cocaína y/o pasta base
A9: (2) Prevalentes de último año de drogas y/o alcohol | H9: (2) Prevalentes de último año de drogas y/o alcohol
A10: Fuente: Elaboración Propia, Décimo Primer Estudio Nacional de Drogas en Población General, SENDA | H10: Fuente: Elaboración Propia, Décimo Primer Estudio Nacional de Drogas en Población General, SENDA
B12: Prevalencia de Consumo Problemático Ultimo Año | I12: N° de Personas con Consumo Problemático Ultimo Año
B13: SEXO | D13: GRUPO DE EDAD | F13: Total | I13: SEXO | K13: GRUPO DE EDAD | M13: Total
B14: Hombre | C14: Mujer | D14: 12-17 años | E14: 18-64 años | I14: Hombre | J14: Mujer | K14: 12-17 años | L14: 18-64 años
A15: Drogas(1) | B15: =B54 -> 25.04141 | C15: =C54 -> 20.62479 | D15: =D54 -> 28.25969 | E15: =E54 -> 23.01197 | F15: =F54 -> 23.46539 | H15: Drogas(1) | I15: =G54 -> 184624.3 | J15: =H54 -> 84366.41 | K15: =I54 -> 27990.43 | L15: =J54 -> 241000.3 | M15: =K54 -> 268990.7
A16: Alcohol(2) | B16: =B55 -> 9.81418 | C16: =C55 -> 4.661084 | D16: =D55 -> 9.175327 | E16: =E55 -> 7.338623 | F16: =F55 -> 7.432098 | H16: Alcohol(2) | I16: =G55 -> 328943.2 | J16: =H55 -> 134298.7 | K16: =I55 -> 29105.63 | L16: =J55 -> 434136.2 | M16: =K55 -> 463241.8
A17: Sustancias | B17: =B56 -> 12.27767 | C17: =C56 -> 5.927048 | D17: =D56 -> 12.81617 | E17: =E56 -> 9.161871 | F17: =F56 -> 9.351972 | H17: Sustancias | I17: =G56 -> 418173.5 | J17: =H56 -> 172447.7 | K17: =I56 -> 42105.78 | L17: =J56 -> 548515.5 | M17: =K56 -> 590621.3
A18: (1) Presencia de síntomas de dependencia (CIE-10) y/o abuso (DSM IV) sobre quienes declaran consumo de último año de marihuana, cocaína y/o pasta base | H18: (1) Presencia de síntomas de dependencia (CIE-10) y/o abuso (DSM IV) sobre quienes declaran consumo de último año de marihuana, cocaína y/o pasta base
A19: (2) Presencia de a lo menos un síntoma de abuso (DSM IV) sobre quienes declaran consumo de último año de alcohol | H19: (2) Presencia de a lo menos un síntoma de abuso (DSM IV) sobre quienes declaran consumo de último año de alcohol
A20: Fuente: Elaboración Propia, Décimo Primer Estudio Nacional de Drogas en Población General, SENDA | H20: Fuente: Elaboración Propia, Décimo Primer Estudio Nacional de Drogas en Población General, SENDA
B22: Prevalencia Tratamiento el último año (de los problemáticos)(1) | I22: N° de Personas Tratadas el último año (de los problemáticos)(1)
B23: SEXO | D23: GRUPO DE EDAD | F23: Total | I23: SEXO | K23: GRUPO DE EDAD | M23: Total
B24: Hombre | C24: Mujer | D24: 12-17 años | E24: 18-64 años | I24: Hombre | J24: Mujer | K24: 12-17 años | L24: 18-64 años
A25: Drogas | B25: =B57 -> 6.185526 | C25: =C57 -> 3.591213 | D25: =D57 -> 2.073051 | E25: =E57 -> 5.754975 | F25: =F57 -> 5.371844 | H25: Drogas | I25: =G57 -> 11419.99 | J25: =H57 -> 3029.778 | K25: =I57 -> 580.2558 | L25: =J57 -> 13869.51 | M25: =K57 -> 14449.76
A26: Alcohol | B26: =B58 -> 6.46349 | C26: =C58 -> 2.682847 | D26: =D58 -> 1.993621 | E26: =E58 -> 5.593631 | F26: =F58 -> 5.367442 | H26: Alcohol | I26: =G58 -> 21261.21 | J26: =H58 -> 3603.028 | K26: =I58 -> 580.2558 | L26: =J58 -> 24283.98 | M26: =K58 -> 24864.24
A27: Sustancias | B27: =B59 -> 5.784214 | C27: =C59 -> 2.978586 | D27: =D59 -> 1.378091 | E27: =E59 -> 5.24038 | F27: =F59 -> 4.965035 | H27: Sustancias | I27: =G59 -> 24188.05 | J27: =H59 -> 5136.503 | K27: =I59 -> 580.2558 | L27: =J59 -> 28744.3 | M27: =K59 -> 29324.55
A28: (1) Calculado a partir de aquellos individuos que presenten consumo problemático en el último año | H28: (1) Calculado a partir de aquellos individuos que presenten consumo problemático en el último año
A29: Fuente: Elaboración Propia, Décimo Primer Estudio Nacional de Drogas en Población General, SENDA | H29: Fuente: Elaboración Propia, Décimo Primer Estudio Nacional de Drogas en Población General, SENDA
B31: Prevalencia Personas que desearon Tratarse (de los problemáticos no tratados)(1) | I31: N° de Personas que desearon Tratarse (de los problemáticos no tratados)(1)
B32: SEXO | D32: GRUPO DE EDAD | F32: Total | I32: SEXO | K32: GRUPO DE EDAD | M32: Total
B33: Hombre | C33: Mujer | D33: 12-17 años | E33: 18-64 años | I33: Hombre | J33: Mujer | K33: 12-17 años | L33: 18-64 años
A34: Drogas | B34: =B60 -> 18.80488 | C34: =C60 -> 5.033316 | D34: =D60 -> 0.4605893 | E34: =E60 -> 16.08701 | F34: =F60 -> 14.40428 | H34: Drogas | I34: =G60 -> 32570.88 | J34: =H60 -> 4093.93 | K34: =I60 -> 126.2483 | L34: =J60 -> 36538.56 | M34: =K60 -> 36664.8
A35: Alcohol | B35: =B61 -> 8.475057 | C35: =C61 -> 7.705242 | D35: =D61 -> 1.367495 | E35: =E61 -> 8.724255 | F35: =F61 -> 8.245548 | H35: Alcohol | I35: =G61 -> 26076.22 | J35: =H61 -> 10070.42 | K35: =I61 -> 390.0829 | L35: =J61 -> 35756.55 | M35: =K61 -> 36146.64
A36: Sustancias | B36: =B62 -> 12.59681 | C36: =C62 -> 6.524409 | D36: =D62 -> 0.9393812 | E36: =E62 -> 11.57347 | F36: =F62 -> 10.78675 | H36: Sustancias | I36: =G62 -> 49629.59 | J36: =H62 -> 10916.07 | K36: =I62 -> 390.0829 | L36: =J62 -> 60155.58 | M36: =K62 -> 60545.66
A37: (1) Calculado a partir de aquellos individuos que presenten consumo problemático y declaren no haber sido tratados por alcohol y/o drogas | H37: (1) Calculado a partir de aquellos individuos que presenten consumo problemático y declaren no haber sido tratados por alcohol y/o drogas
A38: Fuente: Elaboración Propia, Décimo Primer Estudio Nacional de Drogas en Población General, SENDA | H38: Fuente: Elaboración Propia, Décimo Primer Estudio Nacional de Drogas en Población General, SENDA
B40: Prevalencia Personas que intentaron Tratarse (de los problemáticos no tratados y que deseaban tratarse)(1) | I40: N° de Personas que intentaronTratarse (de los problemáticos no tratados y que deseaban tratarse)(1)
B41: SEXO | D41: GRUPO DE EDAD | F41: Total | I41: SEXO | K41: GRUPO DE EDAD | M41: Total
B42: Hombre | C42: Mujer | D42: 12-17 años | E42: 18-64 años | I42: Hombre | J42: Mujer | K42: 12-17 años | L42: 18-64 años
A43: Drogas | B43: =B63 -> 15.06926 | C43: =C63 -> 32.23814 | D43: sd | E43: =E63 -> 17.045 | F43: =F63 -> 16.98631 | H43: Drogas | I43: =G63 -> 4908.189 | J43: =H63 -> 1319.807 | K43: sd | L43: =J63 -> 6227.996 | M43: =K63 -> 6227.996
A44: Alcohol | B44: =B64 -> 34.80162 | C44: =C64 -> 62.35057 | D44: sd | E44: =E64 -> 42.94013 | F44: =F64 -> 42.47673 | H44: Alcohol | I44: =G64 -> 9074.947 | J44: =H64 -> 6278.963 | K44: sd | L44: =J64 -> 15353.91 | M44: =K64 -> 15353.91
A45: Sustancias | B45: =B65 -> 19.31615 | C45: =C65 -> 58.70942 | D45: sd | E45: =E65 -> 26.58986 | F45: =F65 -> 26.41855 | H45: Sustancias | I45: =G65 -> 9586.524 | J45: =H65 -> 6408.761 | K45: sd | L45: =J65 -> 15995.29 | M45: =K65 -> 15995.29
...

Sheet 2016
B2: Prevalencia de Consumo Ultimo Año | I2: N° de Personas con Consumo Ultimo Año
B3: SEXO | D3: GRUPO DE EDAD | F3: Total | I3: SEXO | K3: GRUPO DE EDAD | M3: Total
B4: Hombre | C4: Mujer | D4: 12-17 años | E4: 18-64 años | I4: Hombre | J4: Mujer | K4: 12-17 años | L4: 18-64 años
A5: Drogas(1) | B5: =B51 -> 18.94103 | C5: =C51 -> 10.69744 | D5: =D51 -> 9.869171 | E5: =E51 -> 15.46769 | F5: =F51 -> 14.82714 | H5: Drogas(1) | I5: =G51 -> 959804.5 | J5: =H51 -> 539998.2 | K5: =I51 -> 114217.5 | L5: =J51 -> 1385585 | M5: =K51 -> 1499803
A6: Alcohol | B6: =B52 -> 68.72478 | C6: =C52 -> 59.09944 | D6: =D52 -> 27.39193 | E6: =E52 -> 68.64074 | F6: =F52 -> 63.92134 | H6: Alcohol | I6: =G52 -> 3482511 | J6: =H52 -> 2983293 | K6: =I52 -> 317011.2 | L6: =J52 -> 6148792 | M6: =K52 -> 6465803
A7: Sustancias(2) | B7: =B53 -> 70.20836 | C7: =C53 -> 59.84 | D7: =D53 -> 28.82305 | E7: =E53 -> 69.7124 | F7: =F53 -> 65.03413 | H7: Sustancias(2) | I7: =G53 -> 3557689 | J7: =H53 -> 3020676 | K7: =I53 -> 333573.9 | L7: =J53 -> 6244791 | M7: =K53 -> 6578364
A8: (1) Prevalentes de último año de marihuana, cocaína y/o pasta base | H8: (1) Prevalentes de último año de marihuana, cocaína y/o pasta base
A9: (2) Prevalentes de último año de drogas y/o alcohol | H9: (2) Prevalentes de último año de drogas y/o alcohol
A10: Fuente: Elaboración Propia, Décimo Segundo Estudio Nacional de Drogas en Población General, SENDA | H10: Fuente: Elaboración Propia, Décimo Segundo Estudio Nacional de Drogas en Población General, SENDA
B12: Prevalencia de Consumo Problemático Ultimo Año | I12: N° de Personas con Consumo Problemático Ultimo Año
B13: SEXO | D13: GRUPO DE EDAD | F13: Total | I13: SEXO | K13: GRUPO DE EDAD | M13: Total
B14: Hombre | C14: Mujer | D14: 12-17 años | E14: 18-64 años | I14: Hombre | J14: Mujer | K14: 12-17 años | L14: 18-64 años
A15: Drogas(1) | B15: =B54 -> 27.6668 | C15: =C54 -> 13.32267 | D15: =D54 -> 33.79438 | E15: =E54 -> 21.57141 | F15: =F54 -> 22.50225 | H15: Drogas(1) | I15: =G54 -> 265547.2 | J15: =H54 -> 71942.2 | K15: =I54 -> 38599.1 | L15: =J54 -> 298890.3 | M15: =K54 -> 337489.3
A16: Alcohol(2) | B16: =B55 -> 11.33904 | C16: =C55 -> 3.572563 | D16: =D55 -> 4.655395 | E16: =E55 -> 7.915459 | F16: =F55 -> 7.755622 | H16: Alcohol(2) | I16: =G55 -> 394883.2 | J16: =H55 -> 106580 | K16: =I55 -> 14758.12 | L16: =J55 -> 486705.1 | M16: =K55 -> 501463.3
A17: Sustancias | B17: =B56 -> 15.19899 | C17: =C56 -> 5.04038 | D17: =D56 -> 12.28427 | E17: =E56 -> 10.44085 | F17: =F56 -> 10.53432 | H17: Sustancias | I17: =G56 -> 540732.7 | J17: =H56 -> 152253.5 | K17: =I56 -> 40977.1 | L17: =J56 -> 652009.1 | M17: =K56 -> 692986.2
A18: (1) Presencia de síntomas de dependencia (CIE-10) y/o abuso (DSM IV) sobre quienes declaran consumo de último año de marihuana, cocaína y/o pasta base | H18: (1) Presencia de síntomas de dependencia (CIE-10) y/o abuso (DSM IV) sobre quienes declaran consumo de último año de marihuana, cocaína y/o pasta base
A19: (2) Presencia de a lo menos un síntoma de abuso (DSM IV) sobre quienes declaran consumo de último año de alcohol | H19: (2) Presencia de a lo menos un síntoma de abuso (DSM IV) sobre quienes declaran consumo de último año de alcohol
A20: Fuente: Elaboración Propia, Décimo Segundo Estudio Nacional de Drogas en Población General, SENDA | H20: Fuente: Elaboración Propia, Décimo Segundo Estudio Nacional de Drogas en Población General, SENDA
B22: Prevalencia Tratamiento el último año (de los problemáticos)(1) | I22: N° de Personas Tratadas el último año (de los problemáticos)(1)
B23: SEXO | D23: GRUPO DE EDAD | F23: Total | I23: SEXO | K23: GRUPO DE EDAD | M23: Total
B24: Hombre | C24: Mujer | D24: 12-17 años | E24: 18-64 años | I24: Hombre | J24: Mujer | K24: 12-17 años | L24: 18-64 años
A25: Drogas | B25: =B57 -> 6.804023 | C25: =C57 -> 9.655709 | D25: =D57 -> 14.59637 | E25: =E57 -> 6.484103 | F25: =F57 -> 7.411914 | H25: Drogas | I25: =G57 -> 18067.89 | J25: =H57 -> 6946.529 | K25: =I57 -> 5634.068 | L25: =J57 -> 19380.35 | M25: =K57 -> 25014.42
A26: Alcohol | B26: =B58 -> 4.741415 | C26: =C58 -> 2.089793 | D26: =D58 -> 9.582981 | E26: =E58 -> 4.013947 | F26: =F58 -> 4.177844 | H26: Alcohol | I26: =G58 -> 18723.05 | J26: =H58 -> 2227.302 | K26: =I58 -> 1414.268 | L26: =J58 -> 19536.08 | M26: =K58 -> 20950.35
A27: Sustancias | B27: =B59 -> 4.56408 | C27: =C59 -> 4.71069 | D27: =D59 -> 13.74931 | E27: =E59 -> 4.021048 | F27: =F59 -> 4.596292 | H27: Sustancias | I27: =G59 -> 24679.47 | J27: =H59 -> 7172.192 | K27: =I59 -> 5634.068 | L27: =J59 -> 26217.6 | M27: =K59 -> 31851.67
A28: (1) Calculado a partir de aquellos individuos que presenten consumo problemático en el último año | H28: (1) Calculado a partir de aquellos individuos que presenten consumo problemático en el último año
A29: Fuente: Elaboración Propia, Décimo Segundo Estudio Nacional de Drogas en Población General, SENDA | H29: Fuente: Elaboración Propia, Décimo Segundo Estudio Nacional de Drogas en Población General, SENDA
B31: Prevalencia Personas que desearon Tratarse (de los problemáticos no tratados)(1) | I31: N° de Personas que desearon Tratarse (de los problemáticos no tratados)(1)
B32: SEXO | D32: GRUPO DE EDAD | F32: Total | I32: SEXO | K32: GRUPO DE EDAD | M32: Total
B33: Hombre | C33: Mujer | D33: 12-17 años | E33: 18-64 años | I33: Hombre | J33: Mujer | K33: 12-17 años | L33: 18-64 años
A34: Drogas | B34: =B60 -> 10.47851 | C34: =C60 -> 12.1153 | D34: =D60 -> 0 | E34: =E60 -> 12.09494 | F34: =F60 -> 10.81897 | H34: Drogas | I34: =G60 -> 25932.14 | J34: =H60 -> 7874.42 | K34: =I60 -> 0 | L34: =J60 -> 33806.57 | M34: =K60 -> 33806.57
A35: Alcohol | B35: =B61 -> 10.73859 | C35: =C61 -> 12.84556 | D35: =D61 -> 0 | E35: =E61 -> 11.51596 | F35: =F61 -> 11.19616 | H35: Alcohol | I35: =G61 -> 40394.31 | J35: =H61 -> 13404.69 | K35: =I61 -> 0 | L35: =J61 -> 53799 | M35: =K61 -> 53799
A36: Sustancias | B36: =B62 -> 10.81849 | C36: =C62 -> 9.239432 | D36: =D62 -> 0 | E36: =E62 -> 11.06341 | F36: =F62 -> 10.47198 | H36: Sustancias | I36: =G62 -> 55829.16 | J36: =H62 -> 13404.69 | K36: =I62 -> 0 | L36: =J62 -> 69233.85 | M36: =K62 -> 69233.85
A37: (1) Calculado a partir de aquellos individuos que presenten consumo problemático y declaren no haber sido tratados por alcohol y/o drogas | H37: (1) Calculado a partir de aquellos individuos que presenten consumo problemático y declaren no haber sido tratados por alcohol y/o drogas
A38: Fuente: Elaboración Propia, Décimo Segundo Estudio Nacional de Drogas en Población General, SENDA | H38: Fuente: Elaboración Propia, Décimo Segundo Estudio Nacional de Drogas en Población General, SENDA
B40: Prevalencia Personas que intentaron Tratarse (de los problemáticos no tratados y que deseaban tratarse)(1) | I40: N° de Personas que intentaronTratarse (de los problemáticos no tratados y que deseaban tratarse)(1)
B41: SEXO | D41: GRUPO DE EDAD | F41: Total | I41: SEXO | K41: GRUPO DE EDAD | M41: Total
B42: Hombre | C42: Mujer | D42: 12-17 años | E42: 18-64 años | I42: Hombre | J42: Mujer | K42: 12-17 años | L42: 18-64 años
A43: Drogas | B43: =B63 -> 27.15911 | C43: =C63 -> 79.11831 | D43: =D63 | E43: =E63 -> 39.26175 | F43: =F63 -> 39.26175 | H43: Drogas | I43: =G63 -> 7042.94 | J43: =H63 -> 6230.108 | K43: =I63 -> 0 | L43: =J63 -> 13273.05 | M43: =K63 -> 13273.05
A44: Alcohol | B44: =B64 -> 49.13541 | C44: =C64 -> 60.06263 | D44: =D64 | E44: =E64 -> 51.85806 | F44: =F64 -> 51.85806 | H44: Alcohol | I44: =G64 -> 19847.91 | J44: =H64 -> 8051.21 | K44: =I64 -> 0 | L44: =J64 -> 27899.12 | M44: =K64 -> 27899.12
A45: Sustancias | B45: =B65 -> 40.33533 | C45: =C65 -> 60.06263 | D45: =D65 | E45: =E65 -> 44.15483 | F45: =F65 -> 44.15483 | H45: Sustancias | I45: =G65 -> 22518.88 | J45: =H65 -> 8051.21 | K45: =I65 -> 0 | L45: =J65 -> 30570.09 | M45: =K65 -> 30570.09
...

Sheet 2018
B2: Prevalencia de Consumo Ultimo Año | I2: N° de Personas con Consumo Ultimo Año
B3: SEXO | D3: GRUPO DE EDAD | F3: Total | I3: SEXO | K3: GRUPO DE EDAD | M3: Total
B4: Hombre | C4: Mujer | D4: 12-17 años | E4: 18-64 años | I4: Hombre | J4: Mujer | K4: 12-17 años | L4: 18-64 años
A5: Drogas(1) | B5: =B51 -> 18.69316 | C5: =C51 -> 7.587335 | D5: =D51 -> 7.572773 | E5: =E51 -> 13.7431 | F5: =F51 -> 13.10069 | H5: Drogas(1) | I5: =G51 -> 994808.1 | J5: =H51 -> 409575.3 | K5: =I51 -> 84518.04 | L5: =J51 -> 1319865 | M5: =K51 -> 1404383
A6: Alcohol | B6: =B52 -> 67.56094 | C6: =C52 -> 54.50463 | D6: =D52 -> 26.33183 | E6: =E52 -> 65.01353 | F6: =F52 -> 60.98628 | H6: Alcohol | I6: =G52 -> 3595441 | J6: =H52 -> 2942239 | K6: =I52 -> 293883.8 | L6: =J52 -> 6243796 | M6: =K52 -> 6537680
A7: Sustancias(2) | B7: =B53 -> 68.94612 | C7: =C53 -> 55.48854 | D7: =D53 -> 28.36227 | E7: =E53 -> 66.09818 | F7: =F53 -> 62.16939 | H7: Sustancias(2) | I7: =G53 -> 3669157 | J7: =H53 -> 2995352 | K7: =I53 -> 316545 | L7: =J53 -> 6347964 | M7: =K53 -> 6664509
A8: (1) Prevalentes de último año de marihuana, cocaína y/o pasta base | H8: (1) Prevalentes de último año de marihuana, cocaína y/o pasta base
A9: (2) Prevalentes de último año de drogas y/o alcohol | H9: (2) Prevalentes de último año de drogas y/o alcohol
A10: Fuente: Elaboración Propia, Décimo Tercer Estudio Nacional de Drogas en Población General, SENDA | H10: Fuente: Elaboración Propia, Décimo Tercer Estudio Nacional de Drogas en Población General, SENDA
B12: Prevalencia de Consumo Problemático Ultimo Año | I12: N° de Personas con Consumo Problemático Ultimo Año
B13: SEXO | D13: GRUPO DE EDAD | F13: Total | I13: SEXO | K13: GRUPO DE EDAD | M13: Total
B14: Hombre | C14: Mujer | D14: 12-17 años | E14: 18-64 años | I14: Hombre | J14: Mujer | K14: 12-17 años | L14: 18-64 años
A15: Drogas(1) | B15: =B54 -> 31.58217 | C15: =C54 -> 15.75701 | D15: =D54 -> 15.63365 | E15: =E54 -> 27.69264 | F15: =F54 -> 26.96691 | H15: Drogas(1) | I15: =G54 -> 314182 | J15: =H54 -> 64536.81 | K15: =I54 -> 13213.25 | L15: =J54 -> 365505.6 | M15: =K54 -> 378718.8
A16: Alcohol(2) | B16: =B55 -> 8.116549 | C16: =C55 -> 3.260139 | D16: =D55 -> 2.353411 | E16: =E55 -> 6.099343 | F16: =F55 -> 5.930954 | H16: Alcohol(2) | I16: =G55 -> 291825.8 | J16: =H55 -> 95921.08 | K16: =I55 -> 6916.294 | L16: =J55 -> 380830.5 | M16: =K55 -> 387746.8
A17: Sustancias | B17: =B56 -> 13.8913 | C17: =C56 -> 4.656082 | D17: =D56 -> 5.42807 | E17: =E56 -> 9.955591 | F17: =F56 -> 9.740547 | H17: Sustancias | I17: =G56 -> 509693.6 | J17: =H56 -> 139466 | K17: =I56 -> 17182.29 | L17: =J56 -> 631977.3 | M17: =K56 -> 649159.6
A18: (1) Presencia de síntomas de dependencia (CIE-10) y/o abuso (DSM IV) sobre quienes declaran consumo de último año de marihuana, cocaína y/o pasta base | H18: (1) Presencia de síntomas de dependencia (CIE-10) y/o abuso (DSM IV) sobre quienes declaran consumo de último año de marihuana, cocaína y/o pasta base
A19: (2) Presencia de a lo menos un síntoma de abuso (DSM IV) sobre quienes declaran consumo de último año de alcohol | H19: (2) Presencia de a lo menos un síntoma de abuso (DSM IV) sobre quienes declaran consumo de último año de alcohol
A20: Fuente: Elaboración Propia, Décimo Tercer Estudio Nacional de Drogas en Población General, SENDA | H20: Fuente: Elaboración Propia, Décimo Tercer Estudio Nacional de Drogas en Población General, SENDA
B22: Prevalencia Tratamiento el último año (de los problemáticos)(1) | I22: N° de Personas Tratadas el último año (de los problemáticos)(1)
B23: SEXO | D23: GRUPO DE EDAD | F23: Total | I23: SEXO | K23: GRUPO DE EDAD | M23: Total
B24: Hombre | C24: Mujer | D24: 12-17 años | E24: 18-64 años | I24: Hombre | J24: Mujer | K24: 12-17 años | L24: 18-64 años
A25: Drogas | B25: =B57 -> 3.965467 | C25: =C57 -> 6.475714 | D25: =D57 -> 2.288761 | E25: =E57 -> 4.469312 | F25: =F57 -> 4.393234 | H25: Drogas | I25: =G57 -> 12458.78 | J25: =H57 -> 4179.219 | K25: =I57 -> 302.4198 | L25: =J57 -> 16335.58 | M25: =K57 -> 16638
A26: Alcohol | B26: =B58 -> 6.556698 | C26: =C58 -> 6.058993 | D26: =D58 -> 0 | E26: =E58 -> 6.550416 | F26: =F58 -> 6.433575 | H26: Alcohol | I26: =G58 -> 19134.13 | J26: =H58 -> 5811.852 | K26: =I58 -> 0 | L26: =J58 -> 24945.98 | M26: =K58 -> 24945.98
A27: Sustancias | B27: =B59 -> 4.936451 | C27: =C59 -> 4.384058 | D27: =D59 -> 1.760067 | E27: =E59 -> 4.900908 | F27: =F59 -> 4.817774 | H27: Sustancias | I27: =G59 -> 25160.78 | J27: =H59 -> 6114.271 | K27: =I59 -> 302.4198 | L27: =J59 -> 30972.63 | M27: =K59 -> 31275.05 | O27: =L27+L36 -> 109502.47
A28: (1) Calculado a partir de aquellos individuos que presenten consumo problemático en el último año | H28: (1) Calculado a partir de aquellos individuos que presenten consumo problemático en el último año
A29: Fuente: Elaboración Propia, Décimo Tercer Estudio Nacional de Drogas en Población General, SENDA | H29: Fuente: Elaboración Propia, Décimo Tercer Estudio Nacional de Drogas en Población General, SENDA
B31: Prevalencia Personas que desearon Tratarse (de los problemáticos no tratados)(1) | I31: N° de Personas que desearon Tratarse (de los problemáticos no tratados)(1)
B32: SEXO | D32: GRUPO DE EDAD | F32: Total | I32: SEXO | K32: GRUPO DE EDAD | M32: Total
B33: Hombre | C33: Mujer | D33: 12-17 años | E33: 18-64 años | I33: Hombre | J33: Mujer | K33: 12-17 años | L33: 18-64 años
A34: Drogas | B34: =B60 -> 12.30289 | C34: =C60 -> 12.99497 | D34: =D60 -> 0 | E34: =E60 -> 12.87743 | F34: =F60 -> 12.41826 | H34: Drogas | I34: =G60 -> 37120.67 | J34: =H60 -> 7843.454 | K34: =I60 -> 0 | L34: =J60 -> 44964.13 | M34: =K60 -> 44964.13
A35: Alcohol | B35: =B61 -> 12.83585 | C35: =C61 -> 17.44702 | D35: =D61 -> 2.11636 | E35: =E61 -> 14.21172 | F35: =F61 -> 13.98113 | H35: Alcohol | I35: =G61 -> 35002.3 | J35: =H61 -> 15721.38 | K35: =I61 -> 146.3737 | L35: =J61 -> 50577.3 | M35: =K61 -> 50723.68
A36: Sustancias | B36: =B62 -> 11.66796 | C36: =C62 -> 16.60356 | D36: =D62 -> 0.8671496 | E36: =E62 -> 13.06643 | F36: =F62 -> 12.73316 | H36: Sustancias | I36: =G62 -> 56535.07 | J36: =H62 -> 22141.14 | K36: =I62 -> 146.3737 | L36: =J62 -> 78529.84 | M36: =K62 -> 78676.21
A37: (1) Calculado a partir de aquellos individuos que presenten consumo problemático y declaren no haber sido tratados por alcohol y/o drogas | H37: (1) Calculado a partir de aquellos individuos que presenten consumo problemático y declaren no haber sido tratados por alcohol y/o drogas
A38: Fuente: Elaboración Propia, Décimo Tercer Estudio Nacional de Drogas en Población General, SENDA | H38: Fuente: Elaboración Propia, Décimo Tercer Estudio Nacional de Drogas en Población General, SENDA
B40: Prevalencia Personas que intentaron Tratarse (de los problemáticos no tratados y que deseaban tratarse)(1) | I40: N° de Personas que intentaronTratarse (de los problemáticos no tratados y que deseaban tratarse)(1)
B41: SEXO | D41: GRUPO DE EDAD | F41: Total | I41: SEXO | K41: GRUPO DE EDAD | M41: Total
B42: Hombre | C42: Mujer | D42: 12-17 años | E42: 18-64 años | I42: Hombre | J42: Mujer | K42: 12-17 años | L42: 18-64 años
A43: Drogas | B43: =B63 -> 39.19701 | C43: =C63 -> 23.50634 | D43: =D63 | E43: =E63 -> 36.45996 | F43: =F63 -> 36.45996 | H43: Drogas | I43: =G63 -> 14550.19 | J43: =H63 -> 1843.709 | K43: =I63 -> 0 | L43: =J63 -> 16393.9 | M43: =K63 -> 16393.9
A44: Alcohol | B44: =B64 -> 25.97674 | C44: =C64 -> 92.87556 | D44: =D64 -> 100 | E44: =E64 -> 46.55725 | F44: =F64 -> 46.71147 | H44: Alcohol | I44: =G64 -> 9092.455 | J44: =H64 -> 14601.32 | K44: =I64 -> 146.3737 | L44: =J64 -> 23547.4 | M44: =K64 -> 23693.77
A45: Sustancias | B45: =B65 -> 31.91682 | C45: =C65 -> 70.35563 | D45: =D65 -> 100 | E45: =E65 -> 42.62757 | F45: =F65 -> 42.73431 | H45: Sustancias | I45: =G65 -> 18044.2 | J45: =H65 -> 15577.54 | K45: =I65 -> 146.3737 | L45: =J65 -> 33475.36 | M45: =K65 -> 33621.73
...

Sheet 2020
B2: Prevalencia de Consumo Ultimo Año | I2: N° de Personas con Consumo Ultimo Año
B3: SEXO | D3: GRUPO DE EDAD | F3: Total | I3: SEXO | K3: GRUPO DE EDAD | M3: Total
B4: Hombre | C4: Mujer | D4: 12-17 años | E4: 18-64 años | I4: Hombre | J4: Mujer | K4: 12-17 años | L4: 18-64 años
A5: Drogas(1) | B5: =B51 -> 16.43954 | C5: =C51 -> 6.958605 | D5: =D51 -> 3.740037 | E5: =E51 -> 12.68487 | F5: =F51 -> 11.68358 | H5: Drogas(1) | I5: =G51 -> 892525.3 | J5: =H51 -> 380270.2 | K5: =I51 -> 45608.59 | L5: =J51 -> 1227187 | M5: =K51 -> 1272796 | Q5: =(M5/F5)*100 -> 10893887
A6: Alcohol | B6: =B52 -> 64.9002 | C6: =C52 -> 52.08033 | D6: =D52 -> 19.17954 | E6: =E52 -> 63.42182 | F6: =F52 -> 58.46931 | H6: Alcohol | I6: =G52 -> 3523520 | J6: =H52 -> 2846058 | K6: =I52 -> 233888.6 | L6: =J52 -> 6135690 | M6: =K52 -> 6369579 | Q6: =(M6/F6)*100 -> 10893884
A7: Sustancias(2) | B7: =B53 -> 66.2154 | C7: =C53 -> 52.82986 | D7: =D53 -> 19.95033 | E7: =E53 -> 64.48612 | F7: =F53 -> 59.50075 | H7: Sustancias(2) | I7: =G53 -> 3594924 | J7: =H53 -> 2887018 | K7: =I53 -> 243288.1 | L7: =J53 -> 6238655 | M7: =K53 -> 6481943 | Q7: =(M7/F7)*100 -> 10893885
A8: (1) Prevalentes de último año de marihuana, cocaína y/o pasta base | H8: (1) Prevalentes de último año de marihuana, cocaína y/o pasta base
A9: (2) Prevalentes de último año de drogas y/o alcohol | H9: (2) Prevalentes de último año de drogas y/o alcohol
A10: Fuente: Elaboración Propia, Décimo Cuarto Estudio Nacional de Drogas en Población General, SENDA | H10: Fuente: Elaboración Propia, Décimo Cuarto Estudio Nacional de Drogas en Población General, SENDA | Q10: 10893883 | R10: total de la población estimada
B12: Prevalencia de Consumo Problemático Ultimo Año | I12: N° de Personas con Consumo Problemático Ultimo Año
B13: SEXO | D13: GRUPO DE EDAD | F13: Total | I13: SEXO | K13: GRUPO DE EDAD | M13: Total
B14: Hombre | C14: Mujer | D14: 12-17 años | E14: 18-64 años | I14: Hombre | J14: Mujer | K14: 12-17 años | L14: 18-64 años
A15: Drogas(1) | B15: =B54 -> 30.82305 | C15: =C54 -> 14.74461 | D15: =D54 -> 46.49448 | E15: =E54 -> 25.25837 | F15: =F54 -> 26.01933 | H15: Drogas(1) | I15: =G54 -> 275103.6 | J15: =H54 -> 56069.34 | K15: =I54 -> 21205.48 | L15: =J54 -> 309967.4 | M15: =K54 -> 331172.9
A16: Alcohol(2) | B16: =B55 -> 10.3921 | C16: =C55 -> 1.98044 | D16: =D55 -> 2.889731 | E16: =E55 -> 6.77631 | F16: =F55 -> 6.633596 | H16: Alcohol(2) | I16: =G55 -> 366167.6 | J16: =H55 -> 56364.48 | K16: =I55 -> 6758.751 | L16: =J55 -> 415773.3 | M16: =K55 -> 422532.1
A17: Sustancias | B17: =B56 -> 15.25742 | C17: =C56 -> 3.517062 | D17: =D56 -> 11.34596 | E17: =E56 -> 9.976954 | F17: =F56 -> 10.02834 | H17: Sustancias | I17: =G56 -> 548492.8 | J17: =H56 -> 101538.2 | K17: =I56 -> 27603.38 | L17: =J56 -> 622427.7 | M17: =K56 -> 650031.1 | Q17: =NUMBERVALUE(M16)/M6 -> #NAME? | R17: prevalencia consumo de alcohol entre quienes consumieron ultimo añ
A18: (1) Presencia de síntomas de dependencia (CIE-10) y/o abuso (DSM IV) sobre quienes declaran consumo de último año de marihuana, cocaína y/o pasta base | H18: (1) Presencia de síntomas de dependencia (CIE-10) y/o abuso (DSM IV) sobre quienes declaran consumo de último año de marihuana, cocaína y/o pasta base | Q18: =M17/Q6 -> 0.059669359
A19: (2) Presencia de a lo menos un síntoma de abuso (DSM IV) sobre quienes declaran consumo de último año de alcohol | H19: (2) Presencia de a lo menos un síntoma de abuso (DSM IV) sobre quienes declaran consumo de último año de alcohol
A20: Fuente: Elaboración Propia, Décimo Cuarto Estudio Nacional de Drogas en Población General, SENDA | H20: Fuente: Elaboración Propia, Décimo Cuarto Estudio Nacional de Drogas en Población General, SENDA
B22: Prevalencia Tratamiento el último año (de los problemáticos)(1) | I22: N° de Personas Tratadas el último año (de los problemáticos)(1)
B23: SEXO | D23: GRUPO DE EDAD | F23: Total | I23: SEXO | K23: GRUPO DE EDAD | M23: Total
B24: Hombre | C24: Mujer | D24: 12-17 años | E24: 18-64 años | I24: Hombre | J24: Mujer | K24: 12-17 años | L24: 18-64 años
A25: Drogas | B25: =B57 -> 2.036112 | C25: =C57 -> 6.365247 | D25: =D57 -> 0 | E25: =E57 -> 2.958494 | F25: =F57 -> 2.769057 | H25: Drogas | I25: =G57 -> 5601.416 | J25: =H57 -> 3568.952 | K25: =I57 -> 0 | L25: =J57 -> 9170.367 | M25: =K57 -> 9170.367 | P25: redondeado
A26: Alcohol | B26: =B58 -> 1.559928 | C26: =C58 -> 13.18337 | D26: =D58 -> 0 | E26: =E58 -> 3.161022 | F26: =F58 -> 3.110459 | H26: Alcohol | I26: =G58 -> 5711.951 | J26: =H58 -> 7430.738 | K26: =I58 -> 0 | L26: =J58 -> 13142.69 | M26: =K58 -> 13142.69 | O26: =L27+L36 -> 61249.25 | P26: 61250
A27: Sustancias | B27: =B59 -> 1.495862 | C27: =C59 -> 10.31042 | D27: =D59 -> 0 | E27: =E59 -> 3.000142 | F27: =F59 -> 2.872742 | H27: Sustancias | I27: =G59 -> 8204.698 | J27: =H59 -> 10469.02 | K27: =I59 -> 0 | L27: =J59 -> 18673.71 | M27: =K59 -> 18673.71 | O27: =L27+L36+L45 -> 75211.21
A28: (1) Calculado a partir de aquellos individuos que presenten consumo problemático en el último año | H28: (1) Calculado a partir de aquellos individuos que presenten consumo problemático en el último año
A29: Fuente: Elaboración Propia, Décimo Cuarto Estudio Nacional de Drogas en Población General, SENDA | H29: Fuente: Elaboración Propia, Décimo Cuarto Estudio Nacional de Drogas en Población General, SENDA
B31: Prevalencia Personas que desearon Tratarse (de los problemáticos no tratados)(1) | I31: N° de Personas que desearon Tratarse (de los problemáticos no tratados)(1)
B32: SEXO | D32: GRUPO DE EDAD | F32: Total | I32: SEXO | K32: GRUPO DE EDAD | M32: Total
B33: Hombre | C33: Mujer | D33: 12-17 años | E33: 18-64 años | I33: Hombre | J33: Mujer | K33: 12-17 años | L33: 18-64 años
A34: Drogas | B34: =B60 -> 11.05421 | C34: =C60 -> 5.895754 | D34: =D60 -> 2.566874 | E34: =E60 -> 10.7522 | F34: =F60 -> 10.21316 | H34: Drogas | I34: =G60 -> 29791.33 | J34: =H60 -> 3095.294 | K34: =I60 -> 544.318 | L34: =J60 -> 32342.3 | M34: =K60 -> 32886.62
A35: Alcohol | B35: =B61 -> 5.565617 | C35: =C61 -> 4.338993 | D35: =D61 -> 0 | E35: =E61 -> 5.509966 | F35: =F61 -> 5.419001 | H35: Alcohol | I35: =G61 -> 20061.58 | J35: =H61 -> 2123.232 | K35: =I61 -> 0 | L35: =J61 -> 22184.81 | M35: =K61 -> 22184.81
A36: Sustancias | B36: =B62 -> 7.227829 | C36: =C62 -> 4.467766 | D36: =D62 -> 1.971925 | E36: =E62 -> 7.051803 | F36: =F62 -> 6.829708 | H36: Sustancias | I36: =G62 -> 39051.1 | J36: =H62 -> 4068.759 | K36: =I62 -> 544.318 | L36: =J62 -> 42575.54 | M36: =K62 -> 43119.86
A37: (1) Calculado a partir de aquellos individuos que presenten consumo problemático y declaren no haber sido tratados por alcohol y/o drogas | H37: (1) Calculado a partir de aquellos individuos que presenten consumo problemático y declaren no haber sido tratados por alcohol y/o drogas
A38: Fuente: Elaboración Propia, Décimo Cuarto Estudio Nacional de Drogas en Población General, SENDA | H38: Fuente: Elaboración Propia, Décimo Cuarto Estudio Nacional de Drogas en Población General, SENDA
B40: Prevalencia Personas que intentaron Tratarse (de los problemáticos no tratados y que deseaban tratarse)(1) | I40: N° de Personas que intentaronTratarse (de los problemáticos no tratados y que deseaban tratarse)(1)
B41: SEXO | D41: GRUPO DE EDAD | F41: Total | I41: SEXO | K41: GRUPO DE EDAD | M41: Total
B42: Hombre | C42: Mujer | D42: 12-17 años | E42: 18-64 años | I42: Hombre | J42: Mujer | K42: 12-17 años | L42: 18-64 años
A43: Drogas | B43: =B63 -> 35.64447 | C43: =C63 -> 29.22251 | D43: =D63 -> 100 | E43: =E63 -> 33.94676 | F43: =F63 -> 35.04004 | H43: Drogas | I43: =G63 -> 10618.96 | J43: =H63 -> 904.5226 | K43: =I63 -> 544.318 | L43: =J63 -> 10979.17 | M43: =K63 -> 11523.48
A44: Alcohol | B44: =B64 -> 44.2657 | C44: =C64 -> 33.90398 | D44: =D64 | E44: =E64 -> 43.27402 | F44: =F64 -> 43.27402 | H44: Alcohol | I44: =G64 -> 8880.4 | J44: =H64 -> 719.86 | K44: =I64 -> 0 | L44: =J64 -> 9600.261 | M44: =K64 -> 9600.261
A45: Sustancias | B45: =B65 -> 33.90967 | C45: =C65 -> 31.07036 | D45: =D65 -> 100 | E45: =E65 -> 32.79338 | F45: =F65 -> 33.64176 | H45: Sustancias | I45: =G65 -> 13242.1 | J45: =H65 -> 1264.178 | K45: =I65 -> 544.318 | L45: =J65 -> 13961.96 | M45: =K65 -> 14506.28
...

Sheet ags
A1: https://www.senda.gob.cl/wp-content/uploads/2021/02/Estrategia-Nacional-de-Drogas-version-web.pdf
A2: consumo problemático6 de sustancias, pasando de 692.986 en 2016 a 649.160 en 2018
A3: La definición de consumo problemático de drogas considera a quienes presentan síntomas de abuso de alcohol según DSM-IV y/o presencia de síntomas de abuso DSM-IV o dependencia según CIE-10 para usuarios de último año de marihuana, cocaína y/o pasta base.
A7: https://www.senda.gob.cl/wp-content/uploads/2019/10/Apuntes-Octubre.pdf
A8: El Décimo Segundo Estudio Nacional de Drogas en Población General 2016 también muestra que en ese año existían 152.254 mujeres con consumo problemático de drogas1, de las cuales 7.172 señalan que se trataron en el último año.
A9: 1Se entiende por consumidores problemáticos aquellas personas que consumieron marihuana, cocaína, pasta base y/o alcohol en el último año y que presentaban síntomas de dependencia (CIE-10) y/o abuso (DSM IV) de marihuana, cocaína y/o pasta base y/o presencia de a lo menos un síntoma de abuso (DSM IV) de alcohol.

Sheet comparado
D4: 2010 | E4: 2012 | F4: 2014 | G4: 2016 | H4: 2017 | I4: 2018
C5: Número personas con uso problemático | D5: ='2010'!M17 -> 552961.9 | E5: ='2012'!M17 -> 519278.9 | F5: ='2014'!M17 -> 590621.3 | G5: ='2016'!M17 -> 692986.2 | I5: ='2018'!M17 -> 649159.6 | J5: =(G5-D5)/D5 -> 0.25322595
C6: Deseo tratarse | D6: ='2010'!M36 -> 42822.8 | F6: ='2014'!M36 -> 60545.66 | G6: ='2016'!M36 -> 69233.85 | I6: ='2018'!M36 -> 78676.21 | J6: =(G6-D6)/D6 -> 0.61675206
C7: Tratamiento total | D7: 15196 | E7: 17756 | F7: 25019 | G7: 28257 | H7: 29607 | J7: =(G7-D7)/D7 -> 0.8595025
D9: =D7/D6 -> 0.35485769 | F9: =F7/F6 -> 0.41322532 | G9: =G7/G6 -> 0.4081385
D12: Chile | E12: Mexico | F12: Peru | G12: Uruguay | H12: Brasil
C13: Muertes drogas | D13: 94985 | E13: No disponible | F13: 94741 | G13: 33154 | H13: =J15 -> 1168599
C14: Total | D14: 112 | E14: =531+137 -> 668 | F14: =37+5 -> 42 | G14: =50+6 -> 56 | H14: =1057+865 -> 1922 | J14: 24190 | K14: 0.0207
J15: =J14/K14 -> 1168599 | K15: 1
C16: Total % | D16: =D14/D13 -> 0.0011791335 | E16: =E14/E13 -> #VALUE! | F16: =F14/F13 -> 0.00044331388 | G16: =G14/G13 -> 0.0016890873 | H16: =H14/H13 -> 0.0016447044
C20: -2
C30: 3.2 | E30: 4
C31: 4.3
C32: =(C31-C30)/C30 -> 0.34375
C34: =(C31-E30)/E30 -> 0.075
